Workbook
Name \0: #REF!
Name \0: #REF!
Name \a: #REF!
Name \c: #REF!
Name \g: [1]BP!#REF!
Name \k: [2]KP1590_E!#REF!
Name \L: #REF!
Name \L: #REF!
Name \O: #REF!
Name \O: #REF!
Name \p: '[3]7-2'!#REF!
Name \p: '[3]7-2'!#REF!
Name \r: #REF!
Name \r: #REF!
Name \u: #N/A
Name \V: #REF!
Name \V: #REF!
Name \x: [2]KP1590_E!#REF!
Name \x: [2]KP1590_E!#REF!
Name \z: #REF!
Name \z: #REF!
Name ____ig541: #REF!
Name ____ig541: #REF!
Name ___ann6: [4]!___ann6
Name ___ann6: [5]!___ann6
Name ___Dec1: #REF!
Name ___Dec1: #REF!
Name ___det1855: #REF!
Name ___det1855: #REF!
Name ___det2173: #REF!
Name ___det2173: #REF!
Name ___det2362: #REF!
Name ___det2403: #REF!
Name ___ig541: #REF!
Name ___KC139: #REF!
Name ___Nov02: #REF!
Name ___tp1855: #REF!
Name ___tp2362: #REF!
Name ___tp2403: #REF!
Name ___TR1: #REF!
Name __a5: [6]!Module1.UNITOK
Name __a6: [7]!UNITOK
Name __ann6: [4]!__ann6
Name __ann6: [5]!__ann6
Name __CHF1: #REF!
Name __CHF1: #REF!
Name __DAT18: #REF!
Name __DAT18: #REF!
Name __Dec1: #REF!
Name __Dec1: #REF!
Name __det1855: #REF!
Name __det2173: #REF!
Name __det2362: #REF!
Name __det2403: #REF!
Name __dim4: #REF!
Name __ig541: #REF!
Name __KC139: #REF!
Name __Nov02: #REF!
Name __OPT8: [8]!_xlbgnm.OPT8
Name __OPT9: [8]!_xlbgnm.OPT9

Sheet instructions
B2: Instructions:
B4: 1. | C4: "NPV PT" is the main sheet for the DCF calculations
B5: 2. | C5: Please open your own sheets (working sheet) for the detailed calculations (investment case, base case etc), but use the NPV PT sheet for the NPV/DCF calculations
B6: 3. | C6: The yellow cells are the ones which needs either direct inputs or inputs through linking to other (your) sheets. Grey lines do have formulas
B7: 4. | C7: Select you country from the drop down list in cell C2 in the "NPV PT" sheet
C8: (for European projects you can select "Euro area")
B9: 5. | C9: FX rates and inflation will be automatically populated from the blue book data (a hidden sheet) - please check the date - if there is new bluebook assumption please copy the new ones into the hidden sheets
B10: 6. | C10: Tax rates will aslo be populated. The rates for the major countries have been obtained from BP Global tax team, for the rest the rates were taken from the KPMG site.
C11: You can see the source in cell P15 in the "NPV PT" sheet. If it indicate "KPMG", then refer to local Tax team for reconfirmation.
B12: 7. | C12: Lines 16 to 22 are to be used if there is an incremantal volume /GM due to the project
B13: 8. | C13: Capex and Depr are in a separate sheet - "Capex&Depr"
B14: 9. | C14: Capex Creditors (line 53) need to be inserted by the use. Advise would be that Capex spend in Q4 is assumed to be cashed out the next year
B15: 10. | C15: Please add lines in case the headings in the sheet are not enough - both for P/L and Cash Flow
B16: 11. | C16: The outputs of the DCF are between lines 70-73
B17: 12. | C17: And there are some additional BP metrics between lines 86-96. In case new lines are added to the DCF, the BP metrics may need to be adjusted
B18: 13. | C18: The outputs are also visible in the Summary sheet - with an FM format. Please hide any lines which are not relevant
B19: 14. | C19: In the summary sheet, between lines 6-14 please hide the metrics which are not relevant
B20: 15. | C20: the NTE calculations are in sheet "NPV NTE". The sheet gets the numbers from sheet "NPV PT", the only difference is that it adds the NTE extra request as per the % in column D.
C21: In case this simple rule does not work please ammend the lines directly
B22: 16. | C22: The CashFlow sheet is automatically populated - but if any lines added to the DCF please check the links are correct
B23: 17. | C23: Length of the project is 10 years in the template, but it will change depending on the nature of the projectsi life of assets etc. Please deletete excess columns if less then 10 years,
C24: or add additional columns and copy formulas if need to be more then 15 years.
B25: 18. | C25: A sheet was added re frequently made mistakes - please analyze the sheet before starting or finalizing
B26: 19. | C26: Another sheet was added for the asset useful lives - the recent changes are seen in a separate column (column F)
B27: 20. | C27: The grey sheets are info sheets, the white sheets are working sheets, yellow sheets are the charts needed for the big FM's, and the green ones are the main DCF sheets
B28: 21. | C28: Signages:
C29: + : income / asset / cash-in
C30: – : expense / liability / cash-out

Sheet summary
B3: Expected Impact on External bp Metrics:
C5: bp Net @ central price | D5: ='NPV PT'!D10 -> 2025 | E5: ='NPV PT'!E10 -> 2026 | F5: ='NPV PT'!F10 -> 2027 | G5: ='NPV PT'!G10 -> 2028 | H5: ='NPV PT'!H10 -> 2029 | I5: ='NPV PT'!I10 -> 2030 | J5: TOTAL
C6: Cash Capex | D6: ='NPV PT'!D92/1000000 -> -0.29745902 | E6: ='NPV PT'!E92/1000000 -> 0 | F6: ='NPV PT'!F92/1000000 -> 0 | G6: ='NPV PT'!G92/1000000 -> 0 | H6: ='NPV PT'!H92/1000000 -> 0 | I6: ='NPV PT'!I92/1000000 -> 0 | J6: ='NPV PT'!O92/1000000 -> -0.29745902
C7: Revex | D7: ='NPV PT'!D93/1000000 -> 0 | E7: ='NPV PT'!E93/1000000 -> 0 | F7: ='NPV PT'!F93/1000000 -> 0 | G7: ='NPV PT'!G93/1000000 -> 0 | H7: ='NPV PT'!H93/1000000 -> 0 | I7: ='NPV PT'!I93/1000000 -> 0 | J7: ='NPV PT'!O93/1000000 -> 0
C8: Remediation | D8: ='NPV PT'!D94/1000000 -> 0 | E8: ='NPV PT'!E94/1000000 -> 0 | F8: ='NPV PT'!F94/1000000 -> 0 | G8: ='NPV PT'!G94/1000000 -> 0 | H8: ='NPV PT'!H94/1000000 -> 0 | I8: ='NPV PT'!I94/1000000 -> 0 | J8: ='NPV PT'!O94/1000000 -> 0
C9: Ratex | D9: ='NPV PT'!D95/1000000 -> 0 | E9: ='NPV PT'!E95/1000000 -> 0 | F9: ='NPV PT'!F95/1000000 -> 0 | G9: ='NPV PT'!G95/1000000 -> 0 | H9: ='NPV PT'!H95/1000000 -> 0 | I9: ='NPV PT'!I95/1000000 -> 0 | J9: ='NPV PT'!O95/1000000 -> 0
C10: Post tax free cash flow ($m) | D10: ='NPV PT'!D99/1000000 -> -0.36200255 | E10: ='NPV PT'!E99/1000000 -> 0.66762068 | F10: ='NPV PT'!F99/1000000 -> 0.66848631 | G10: ='NPV PT'!G99/1000000 -> 0.66906031 | H10: ='NPV PT'!H99/1000000 -> 0.66949466 | I10: ='NPV PT'!I99/1000000 -> 0.66985794 | J10: ='NPV PT'!O99/1000000 -> 2.9825174
C11: Underlying RCOP ($m) | D11: ='NPV PT'!D101/1000000 -> -0.053503185 | E11: ='NPV PT'!E101/1000000 -> 0.79013503 | F11: ='NPV PT'!F101/1000000 -> 0.78652822 | G11: ='NPV PT'!G101/1000000 -> 0.78413656 | H11: ='NPV PT'!H101/1000000 -> 0.78232675 | I11: ='NPV PT'!I101/1000000 -> 0.78081308 | J11: ='NPV PT'!O101/1000000 -> 3.8704365
C12: GHG S1 & S2 emissions (kt, CO2e)
C13: · A lease asset and liability will be reported on the balance sheet from the start of the lease in [date] of $[X]m with lease payments of $[X]m per annum.
C14: · [Enter business group specific metrics].
M17: Economics:
N19: Blue Book Price/Margin | O19: Sensitivity Case | P19: Financial Request $m | Q19: NPV | R19: IRR | S19: PI | T19: DP
Q20: $m | R20: % | S20: $/$ | T20: Years
N21: Central | O21: NTE | P21: =-('NPV NTE'!P92+'NPV NTE'!P93+'NPV NTE'!P94+'NPV NTE'!P95)/1000000 -> 0.30981826 | Q21: ='NPV NTE'!C75 -> 2.2918439 | R21: ='NPV NTE'!C76*100 -> 177.52775 | S21: ='NPV NTE'!C78 -> 2.2334567 | T21: ='NPV NTE'!C77 -> 1.5994358
O22: PT | P22: =-('NPV PT'!O92+'NPV PT'!O93+'NPV PT'!O94+'NPV PT'!O95)/1000000 -> 0.29745902 | Q22: ='NPV PT'!C75 -> 2.3011519 | R22: ='NPV PT'!C76*100 -> 183.5252 | S22: ='NPV PT'!C78 -> 2.2475294 | T22: ='NPV PT'!C77 -> 1.5801838

Sheet NPV PT
B2: Country | C2: Malaysia
B3: Cost of Capital | C3: 0.08 | F3: Project X
D8: 0 | E8: 1 | F8: 2 | G8: 3 | H8: 4 | I8: 5 | J8: 6 | K8: 7 | L8: 8 | M8: 9 | N8: 10
B9: Particulars | D9: Year 0 | E9: Year 1 | F9: Year 2 | G9: Year 3 | H9: Year 4 | I9: Year 5 | J9: Year 6 | K9: Year 7 | L9: Year 8 | M9: Year 9 | N9: Year 10
D10: 2025 | E10: =D10+1 -> 2026 | F10: =E10+1 -> 2027 | G10: =F10+1 -> 2028 | H10: =G10+1 -> 2029 | I10: =H10+1 -> 2030 | J10: =I10+1 -> 2031 | K10: =J10+1 -> 2032 | L10: =K10+1 -> 2033 | ... N10: =M10+1 -> 2035
B11: GIAAP
B12: FX rates | C12: =CONCATENATE(VLOOKUP($C$2,countries!C:F,4,0),"/USD") -> MYR/USD | D12: =IF(VLOOKUP($C$2,countries!$C:$D,2,0)="Euro area",1/VLOOKUP(VLOOKUP($C$2,countries!$C:$D,2,0),'BB FX'!$B:$AE,D8+4,0),VLOOKUP(VLOOKUP($C$2,countries!$C:$D,2,0),'BB FX'!$B:$AE,D8+4,0)) -> 4.71 | E12: =IF(VLOOKUP($C$2,countries!$C:$D,2,0)="Euro area",1/VLOOKUP(VLOOKUP($C$2,countries!$C:$D,2,0),'BB FX'!$B:$AE,E8+4,0),VLOOKUP(VLOOKUP($C$2,countries!$C:$D,2,0),'BB FX'!$B:$AE,E8+4,0)) -> 4.51 | F12: =IF(VLOOKUP($C$2,countries!$C:$D,2,0)="Euro area",1/VLOOKUP(VLOOKUP($C$2,countries!$C:$D,2,0),'BB FX'!$B:$AE,F8+4,0),VLOOKUP(VLOOKUP($C$2,countries!$C:$D,2,0),'BB FX'!$B:$AE,F8+4,0)) -> 4.28 | G12: =IF(VLOOKUP($C$2,countries!$C:$D,2,0)="Euro area",1/VLOOKUP(VLOOKUP($C$2,countries!$C:$D,2,0),'BB FX'!$B:$AE,G8+4,0),VLOOKUP(VLOOKUP($C$2,countries!$C:$D,2,0),'BB FX'!$B:$AE,G8+4,0)) -> 4.14 | H12: =IF(VLOOKUP($C$2,countries!$C:$D,2,0)="Euro area",1/VLOOKUP(VLOOKUP($C$2,countries!$C:$D,2,0),'BB FX'!$B:$AE,H8+4,0),VLOOKUP(VLOOKUP($C$2,countries!$C:$D,2,0),'BB FX'!$B:$AE,H8+4,0)) -> 4.04 | I12: =IF(VLOOKUP($C$2,countries!$C:$D,2,0)="Euro area",1/VLOOKUP(VLOOKUP($C$2,countries!$C:$D,2,0),'BB FX'!$B:$AE,I8+4,0),VLOOKUP(VLOOKUP($C$2,countries!$C:$D,2,0),'BB FX'!$B:$AE,I8+4,0)) -> 3.96 | J12: =IF(VLOOKUP($C$2,countries!$C:$D,2,0)="Euro area",1/VLOOKUP(VLOOKUP($C$2,countries!$C:$D,2,0),'BB FX'!$B:$AE,J8+4,0),VLOOKUP(VLOOKUP($C$2,countries!$C:$D,2,0),'BB FX'!$B:$AE,J8+4,0)) -> 3.91 | K12: =IF(VLOOKUP($C$2,countries!$C:$D,2,0)="Euro area",1/VLOOKUP(VLOOKUP($C$2,countries!$C:$D,2,0),'BB FX'!$B:$AE,K8+4,0),VLOOKUP(VLOOKUP($C$2,countries!$C:$D,2,0),'BB FX'!$B:$AE,K8+4,0)) -> 3.88 | ... N12: =IF(VLOOKUP($C$2,countries!$C:$D,2,0)="Euro area",1/VLOOKUP(VLOOKUP($C$2,countries!$C:$D,2,0),'BB FX'!$B:$AE,N8+4,0),VLOOKUP(VLOOKUP($C$2,countries!$C:$D,2,0),'BB FX'!$B:$AE,N8+4,0)) -> 3.83
B13: Inflation Rates | C13: % | D13: =VLOOKUP($C$2,'BB inflation'!$B:$AE,D8+4,0)/100 -> 0.02385 | E13: =VLOOKUP($C$2,'BB inflation'!$B:$AE,E8+4,0)/100 -> 0.0273 | F13: =VLOOKUP($C$2,'BB inflation'!$B:$AE,F8+4,0)/100 -> 0.0259 | G13: =VLOOKUP($C$2,'BB inflation'!$B:$AE,G8+4,0)/100 -> 0.02595 | H13: =VLOOKUP($C$2,'BB inflation'!$B:$AE,H8+4,0)/100 -> 0.0235 | I13: =VLOOKUP($C$2,'BB inflation'!$B:$AE,I8+4,0)/100 -> 0.024 | J13: =VLOOKUP($C$2,'BB inflation'!$B:$AE,J8+4,0)/100 -> 0.0243 | K13: =VLOOKUP($C$2,'BB inflation'!$B:$AE,K8+4,0)/100 -> 0.0243 | ... N13: =VLOOKUP($C$2,'BB inflation'!$B:$AE,N8+4,0)/100 -> 0.02355
B14: Cumm Inflation Rates | C14: % | E14: =(1+D14)*(1+D13)-1 -> 0.02385 | F14: =(1+E14)*(1+E13)-1 -> 0.051801105 | G14: =(1+F14)*(1+F13)-1 -> 0.079042754 | H14: =(1+G14)*(1+G13)-1 -> 0.10704391 | I14: =(1+H14)*(1+H13)-1 -> 0.13305945 | J14: =(1+I14)*(1+I13)-1 -> 0.16025287 | K14: =(1+J14)*(1+J13)-1 -> 0.18844702 | L14: =(1+K14)*(1+K13)-1 -> 0.21732628 | ... N14: =(1+M14)*(1+M13)-1 -> 0.2762098 | P14: tax info from:
B15: Tax rate | C15: % | D15: =VLOOKUP($C$2,'tax rates'!$B:$AE,D$8+4,0)/100 -> 0.24 | E15: =VLOOKUP($C$2,'tax rates'!$B:$AE,E$8+4,0)/100 -> 0.24 | F15: =VLOOKUP($C$2,'tax rates'!$B:$AE,F$8+4,0)/100 -> 0.24 | G15: =VLOOKUP($C$2,'tax rates'!$B:$AE,G$8+4,0)/100 -> 0.24 | H15: =VLOOKUP($C$2,'tax rates'!$B:$AE,H$8+4,0)/100 -> 0.24 | I15: =VLOOKUP($C$2,'tax rates'!$B:$AE,I$8+4,0)/100 -> 0.24 | J15: =VLOOKUP($C$2,'tax rates'!$B:$AE,J$8+4,0)/100 -> 0.24 | K15: =VLOOKUP($C$2,'tax rates'!$B:$AE,K$8+4,0)/100 -> 0.24 | ... N15: =VLOOKUP($C$2,'tax rates'!$B:$AE,N$8+4,0)/100 -> 0.24 | P15: =VLOOKUP(C2,'tax rates'!B:AF,31,0) -> BP tax - 2023 | Q15: -----> please check / reconfirm with your local tax also (especially if info is from KPMG source)
B16: Assumptions
B17: Additional Sales Volume | C17: lt | E17: ='Working - MY OU 5% Imrpovement'!E6 -> 1511910.2 | F17: ='Working - MY OU 5% Imrpovement'!F6 -> 1511910.2 | G17: ='Working - MY OU 5% Imrpovement'!G6 -> 1511910.2 | H17: ='Working - MY OU 5% Imrpovement'!H6 -> 1511910.2 | I17: ='Working - MY OU 5% Imrpovement'!I6 -> 1511910.2 | O17: -----> if there is additional sales volume
B18: Unit Margin | C18: =CONCATENATE(VLOOKUP($C$2,countries!C:F,4,0),"/lt") -> MYR/lt | E18: ='Working - MY OU 5% Imrpovement'!E7*E12 -> 4.059 | F18: ='Working - MY OU 5% Imrpovement'!F7*F12 -> 3.852 | G18: ='Working - MY OU 5% Imrpovement'!G7*G12 -> 3.726 | H18: ='Working - MY OU 5% Imrpovement'!H7*H12 -> 3.636 | I18: ='Working - MY OU 5% Imrpovement'!I7*I12 -> 3.564
B19: Unit COGS | C19: =CONCATENATE(VLOOKUP($C$2,countries!C:F,4,0),"/lt") -> MYR/lt
B20: Unit Margin | C20: =CONCATENATE(VLOOKUP($C$2,countries!C:F,4,0),"/lt") -> MYR/lt | D20: =D18+D19 -> 0 | E20: =E18+E19 -> 4.059 | F20: =F18+F19 -> 3.852 | G20: =G18+G19 -> 3.726 | H20: =H18+H19 -> 3.636 | I20: =I18+I19 -> 3.564 | J20: =J18+J19 -> 0 | K20: =K18+K19 -> 0 | ... N20: =N18+N19 -> 0
B21: Sales Turnover | C21: =VLOOKUP($C$2,countries!C:F,4,0) -> MYR | D21: =D17*D18 -> 0 | E21: =E17*E18 -> 6136843.5 | F21: =F17*F18 -> 5823878.1 | G21: =G17*G18 -> 5633377.4 | H21: =H17*H18 -> 5497305.5 | I21: =I17*I18 -> 5388448 | J21: =J17*J18 -> 0 | K21: =K17*K18 -> 0 | ... N21: =N17*N18 -> 0
B22: COGS | C22: =VLOOKUP($C$2,countries!C:F,4,0) -> MYR | D22: =D17*D19 -> 0 | E22: =E17*E19 -> 0 | F22: =F17*F19 -> 0 | G22: =G17*G19 -> 0 | H22: =H17*H19 -> 0 | I22: =I17*I19 -> 0 | J22: =J17*J19 -> 0 | K22: =K17*K19 -> 0 | ... N22: =N17*N19 -> 0
B23: Profit and Loss
B24: Topline Growth (GM - Additional volume profit) | C24: =VLOOKUP($C$2,countries!C:F,4,0) -> MYR | D24: =D20*D17 -> 0 | E24: =E20*E17 -> 6136843.5 | F24: =F20*F17 -> 5823878.1 | G24: =G20*G17 -> 5633377.4 | H24: =H20*H17 -> 5497305.5 | I24: =I20*I17 -> 5388448 | J24: =J20*J17 -> 0 | K24: =K20*K17 -> 0 | ... N24: =N20*N17 -> 0
B25: Secondary Logs Refund/Rebate (for Indirect channel) | C25: =VLOOKUP($C$2,countries!C:F,4,0) -> MYR
B26: Additional Volume Sec Distribution (TCC) | C26: =VLOOKUP($C$2,countries!C:F,4,0) -> MYR
B27: CFC (TCC) | C27: =VLOOKUP($C$2,countries!C:F,4,0) -> MYR
B28: Marketing costs (TCC) | C28: =VLOOKUP($C$2,countries!C:F,4,0) -> MYR | D28: -400000
B29: ASP | C29: =VLOOKUP($C$2,countries!C:F,4,0) -> MYR
B30: Write-offs (COGS - GM) | C30: =VLOOKUP($C$2,countries!C:F,4,0) -> MYR
B31: Other Income | C31: =VLOOKUP($C$2,countries!C:F,4,0) -> MYR
B32: GSC Savings/Costs (GM) - RM COGS | C32: =VLOOKUP($C$2,countries!C:F,4,0) -> MYR
B33: GSC Savings/Costs (TCC) - Manufacturing | C33: =VLOOKUP($C$2,countries!C:F,4,0) -> MYR
B34: GSC Savings/Costs (TCC) - BU Support | C34: =VLOOKUP($C$2,countries!C:F,4,0) -> MYR
B35: GSC Savings/Costs (ACC) - Primary Logistics | C35: =VLOOKUP($C$2,countries!C:F,4,0) -> MYR
B36: GSC Savings/Costs (ACC) - S&H | C36: =VLOOKUP($C$2,countries!C:F,4,0) -> MYR
B37: GSC Savings/Costs (TCC) - Sec Logistics | C37: =VLOOKUP($C$2,countries!C:F,4,0) -> MYR
B38: GBS cost savings (TCC) | C38: =VLOOKUP($C$2,countries!C:F,4,0) -> MYR
B39: Project Revex (Implementation costs) | C39: =VLOOKUP($C$2,countries!C:F,4,0) -> MYR
B40: Depreciation | C40: =VLOOKUP($C$2,countries!C:F,4,0) -> MYR | D40: =SUM('Capex&Depr'!F20:F29) -> 0 | E40: =SUM('Capex&Depr'!G20:G29) -> -480480 | F40: =SUM('Capex&Depr'!H20:H29) -> -480480 | G40: =SUM('Capex&Depr'!I20:I29) -> -480480 | H40: =SUM('Capex&Depr'!J20:J29) -> -480480 | I40: =SUM('Capex&Depr'!K20:K29) -> -480480 | J40: =SUM('Capex&Depr'!L20:L29) -> 0 | K40: =SUM('Capex&Depr'!M20:M29) -> 0 | ... M40: =SUM('Capex&Depr'!O20:O29) -> 0
B41: Impairment | C41: =VLOOKUP($C$2,countries!C:F,4,0) -> MYR
B42: Remediation & Dismantling Costs | C42: =VLOOKUP($C$2,countries!C:F,4,0) -> MYR
B43: Ratex accrued | C43: =VLOOKUP($C$2,countries!C:F,4,0) -> MYR
B44: Net Profit | C44: =VLOOKUP($C$2,countries!C:F,4,0) -> MYR | D44: =SUM(D23:D43) -> -400000 | E44: =SUM(E23:E43) -> 5656363.5 | F44: =SUM(F23:F43) -> 5343398.1 | G44: =SUM(G23:G43) -> 5152897.4 | H44: =SUM(H23:H43) -> 5016825.5 | I44: =SUM(I23:I43) -> 4907968 | J44: =SUM(J23:J43) -> 0 | K44: =SUM(K23:K43) -> 0 | ... N44: =SUM(N23:N43) -> 0
B45: Interest | C45: =VLOOKUP($C$2,countries!C:F,4,0) -> MYR | D45: 0 | E45: 0 | F45: 0 | G45: 0 | H45: 0 | I45: 0 | J45: 0 | K45: 0 | L45: 0 | M45: 0 | N45: 0
...

Sheet NPV NTE
B2: Country | C2: ='NPV PT'!C2 -> Malaysia
B3: Cost of Capital | C3: ='NPV PT'!C3 -> 0.08 | G3: Project X
E8: 0 | F8: 1 | G8: 2 | H8: 3 | I8: 4 | J8: 5 | K8: 6 | L8: 7 | M8: 8 | N8: 9 | O8: 10
B9: Particulars | D9: NTE extra request | E9: Year 0 | F9: Year 1 | G9: Year 2 | H9: Year 3 | I9: Year 4 | J9: Year 5 | K9: Year 6 | L9: Year 7 | M9: Year 8 | N9: Year 9 | O9: Year 10
E10: ='NPV PT'!D10 -> 2025 | F10: =E10+1 -> 2026 | G10: =F10+1 -> 2027 | H10: =G10+1 -> 2028 | I10: =H10+1 -> 2029 | J10: =I10+1 -> 2030 | K10: =J10+1 -> 2031 | L10: =K10+1 -> 2032 | M10: =L10+1 -> 2033 | ... O10: =N10+1 -> 2035
B11: GIAAP
B12: FX rates | C12: =CONCATENATE(VLOOKUP($C$2,countries!C:F,4,0),"/USD") -> MYR/USD | E12: ='NPV PT'!D12 -> 4.71 | F12: ='NPV PT'!E12 -> 4.51 | G12: ='NPV PT'!F12 -> 4.28 | H12: ='NPV PT'!G12 -> 4.14 | I12: ='NPV PT'!H12 -> 4.04 | J12: ='NPV PT'!I12 -> 3.96 | K12: ='NPV PT'!J12 -> 3.91 | L12: ='NPV PT'!K12 -> 3.88 | ... O12: ='NPV PT'!N12 -> 3.83
B13: Inflation Rates | C13: % | E13: ='NPV PT'!D13 -> 0.02385 | F13: ='NPV PT'!E13 -> 0.0273 | G13: ='NPV PT'!F13 -> 0.0259 | H13: ='NPV PT'!G13 -> 0.02595 | I13: ='NPV PT'!H13 -> 0.0235 | J13: ='NPV PT'!I13 -> 0.024 | K13: ='NPV PT'!J13 -> 0.0243 | L13: ='NPV PT'!K13 -> 0.0243 | ... O13: ='NPV PT'!N13 -> 0.02355
B14: Cumm Inflation Rates | C14: % | E14: ='NPV PT'!D14 -> 0 | F14: ='NPV PT'!E14 -> 0.02385 | G14: ='NPV PT'!F14 -> 0.051801105 | H14: ='NPV PT'!G14 -> 0.079042754 | I14: ='NPV PT'!H14 -> 0.10704391 | J14: ='NPV PT'!I14 -> 0.13305945 | K14: ='NPV PT'!J14 -> 0.16025287 | L14: ='NPV PT'!K14 -> 0.18844702 | ... O14: ='NPV PT'!N14 -> 0.2762098
B15: Tax rate | C15: % | E15: ='NPV PT'!D15 -> 0.24 | F15: ='NPV PT'!E15 -> 0.24 | G15: ='NPV PT'!F15 -> 0.24 | H15: ='NPV PT'!G15 -> 0.24 | I15: ='NPV PT'!H15 -> 0.24 | J15: ='NPV PT'!I15 -> 0.24 | K15: ='NPV PT'!J15 -> 0.24 | L15: ='NPV PT'!K15 -> 0.24 | ... O15: ='NPV PT'!N15 -> 0.24
B16: Assumptions
B17: Additional Volume | C17: lt | E17: =IF($D17="",'NPV PT'!D17,'NPV PT'!D17*(1+$D17)) -> 0 | F17: =IF($D17="",'NPV PT'!E17,'NPV PT'!E17*(1+$D17)) -> 1511910.2 | G17: =IF($D17="",'NPV PT'!F17,'NPV PT'!F17*(1+$D17)) -> 1511910.2 | H17: =IF($D17="",'NPV PT'!G17,'NPV PT'!G17*(1+$D17)) -> 1511910.2 | I17: =IF($D17="",'NPV PT'!H17,'NPV PT'!H17*(1+$D17)) -> 1511910.2 | J17: =IF($D17="",'NPV PT'!I17,'NPV PT'!I17*(1+$D17)) -> 1511910.2 | K17: =IF($D17="",'NPV PT'!J17,'NPV PT'!J17*(1+$D17)) -> 0 | L17: =IF($D17="",'NPV PT'!K17,'NPV PT'!K17*(1+$D17)) -> 0 | ... O17: =IF($D17="",'NPV PT'!N17,'NPV PT'!N17*(1+$D17)) -> 0
B18: Unit Turnover | C18: =CONCATENATE(VLOOKUP($C$2,countries!C:F,4,0),"/lt") -> MYR/lt | E18: =IF($D18="",'NPV PT'!D18,'NPV PT'!D18*(1+$D18)) -> 0 | F18: =IF($D18="",'NPV PT'!E18,'NPV PT'!E18*(1+$D18)) -> 4.059 | G18: =IF($D18="",'NPV PT'!F18,'NPV PT'!F18*(1+$D18)) -> 3.852 | H18: =IF($D18="",'NPV PT'!G18,'NPV PT'!G18*(1+$D18)) -> 3.726 | I18: =IF($D18="",'NPV PT'!H18,'NPV PT'!H18*(1+$D18)) -> 3.636 | J18: =IF($D18="",'NPV PT'!I18,'NPV PT'!I18*(1+$D18)) -> 3.564 | K18: =IF($D18="",'NPV PT'!J18,'NPV PT'!J18*(1+$D18)) -> 0 | L18: =IF($D18="",'NPV PT'!K18,'NPV PT'!K18*(1+$D18)) -> 0 | ... O18: =IF($D18="",'NPV PT'!N18,'NPV PT'!N18*(1+$D18)) -> 0
B19: Unit COGS | C19: =CONCATENATE(VLOOKUP($C$2,countries!C:F,4,0),"/lt") -> MYR/lt | E19: =IF($D19="",'NPV PT'!D19,'NPV PT'!D19*(1+$D19)) -> 0 | F19: =IF($D19="",'NPV PT'!E19,'NPV PT'!E19*(1+$D19)) -> 0 | G19: =IF($D19="",'NPV PT'!F19,'NPV PT'!F19*(1+$D19)) -> 0 | H19: =IF($D19="",'NPV PT'!G19,'NPV PT'!G19*(1+$D19)) -> 0 | I19: =IF($D19="",'NPV PT'!H19,'NPV PT'!H19*(1+$D19)) -> 0 | J19: =IF($D19="",'NPV PT'!I19,'NPV PT'!I19*(1+$D19)) -> 0 | K19: =IF($D19="",'NPV PT'!J19,'NPV PT'!J19*(1+$D19)) -> 0 | L19: =IF($D19="",'NPV PT'!K19,'NPV PT'!K19*(1+$D19)) -> 0 | ... O19: =IF($D19="",'NPV PT'!N19,'NPV PT'!N19*(1+$D19)) -> 0
B20: Unit Margin | C20: =CONCATENATE(VLOOKUP($C$2,countries!C:F,4,0),"/lt") -> MYR/lt | E20: =IF($D20="",'NPV PT'!D20,'NPV PT'!D20*(1+$D20)) -> 0 | F20: =IF($D20="",'NPV PT'!E20,'NPV PT'!E20*(1+$D20)) -> 4.059 | G20: =IF($D20="",'NPV PT'!F20,'NPV PT'!F20*(1+$D20)) -> 3.852 | H20: =IF($D20="",'NPV PT'!G20,'NPV PT'!G20*(1+$D20)) -> 3.726 | I20: =IF($D20="",'NPV PT'!H20,'NPV PT'!H20*(1+$D20)) -> 3.636 | J20: =IF($D20="",'NPV PT'!I20,'NPV PT'!I20*(1+$D20)) -> 3.564 | K20: =IF($D20="",'NPV PT'!J20,'NPV PT'!J20*(1+$D20)) -> 0 | L20: =IF($D20="",'NPV PT'!K20,'NPV PT'!K20*(1+$D20)) -> 0 | ... O20: =IF($D20="",'NPV PT'!N20,'NPV PT'!N20*(1+$D20)) -> 0
B21: Sales Turnover | C21: =VLOOKUP($C$2,countries!C:F,4,0) -> MYR | E21: =IF($D21="",'NPV PT'!D21,'NPV PT'!D21*(1+$D21)) -> 0 | F21: =IF($D21="",'NPV PT'!E21,'NPV PT'!E21*(1+$D21)) -> 6136843.5 | G21: =IF($D21="",'NPV PT'!F21,'NPV PT'!F21*(1+$D21)) -> 5823878.1 | H21: =IF($D21="",'NPV PT'!G21,'NPV PT'!G21*(1+$D21)) -> 5633377.4 | I21: =IF($D21="",'NPV PT'!H21,'NPV PT'!H21*(1+$D21)) -> 5497305.5 | J21: =IF($D21="",'NPV PT'!I21,'NPV PT'!I21*(1+$D21)) -> 5388448 | K21: =IF($D21="",'NPV PT'!J21,'NPV PT'!J21*(1+$D21)) -> 0 | L21: =IF($D21="",'NPV PT'!K21,'NPV PT'!K21*(1+$D21)) -> 0 | ... O21: =IF($D21="",'NPV PT'!N21,'NPV PT'!N21*(1+$D21)) -> 0
B22: COGS | C22: =VLOOKUP($C$2,countries!C:F,4,0) -> MYR | E22: =IF($D22="",'NPV PT'!D22,'NPV PT'!D22*(1+$D22)) -> 0 | F22: =IF($D22="",'NPV PT'!E22,'NPV PT'!E22*(1+$D22)) -> 0 | G22: =IF($D22="",'NPV PT'!F22,'NPV PT'!F22*(1+$D22)) -> 0 | H22: =IF($D22="",'NPV PT'!G22,'NPV PT'!G22*(1+$D22)) -> 0 | I22: =IF($D22="",'NPV PT'!H22,'NPV PT'!H22*(1+$D22)) -> 0 | J22: =IF($D22="",'NPV PT'!I22,'NPV PT'!I22*(1+$D22)) -> 0 | K22: =IF($D22="",'NPV PT'!J22,'NPV PT'!J22*(1+$D22)) -> 0 | L22: =IF($D22="",'NPV PT'!K22,'NPV PT'!K22*(1+$D22)) -> 0 | ... O22: =IF($D22="",'NPV PT'!N22,'NPV PT'!N22*(1+$D22)) -> 0
B23: Profit and Loss
B24: Topline Growth (GM - Additional volume profit) | C24: =VLOOKUP($C$2,countries!C:F,4,0) -> MYR | E24: =E20*E17 -> 0 | F24: =F20*F17 -> 6136843.5 | G24: =G20*G17 -> 5823878.1 | H24: =H20*H17 -> 5633377.4 | I24: =I20*I17 -> 5497305.5 | J24: =J20*J17 -> 5388448 | K24: =K20*K17 -> 0 | L24: =L20*L17 -> 0 | ... O24: =O20*O17 -> 0
B25: Secondary Logs Refund/Rebate (for Indirect channel) | C25: =VLOOKUP($C$2,countries!C:F,4,0) -> MYR | E25: =IF($D25="",'NPV PT'!D25,'NPV PT'!D25*(1+$D25)) -> 0 | F25: =IF($D25="",'NPV PT'!E25,'NPV PT'!E25*(1+$D25)) -> 0 | G25: =IF($D25="",'NPV PT'!F25,'NPV PT'!F25*(1+$D25)) -> 0 | H25: =IF($D25="",'NPV PT'!G25,'NPV PT'!G25*(1+$D25)) -> 0 | I25: =IF($D25="",'NPV PT'!H25,'NPV PT'!H25*(1+$D25)) -> 0 | J25: =IF($D25="",'NPV PT'!I25,'NPV PT'!I25*(1+$D25)) -> 0 | K25: =IF($D25="",'NPV PT'!J25,'NPV PT'!J25*(1+$D25)) -> 0 | L25: =IF($D25="",'NPV PT'!K25,'NPV PT'!K25*(1+$D25)) -> 0 | ... O25: =IF($D25="",'NPV PT'!N25,'NPV PT'!N25*(1+$D25)) -> 0
B26: Additional Volume Sec Distribution (TCC) | C26: =VLOOKUP($C$2,countries!C:F,4,0) -> MYR | E26: =IF($D26="",'NPV PT'!D26,'NPV PT'!D26*(1+$D26)) -> 0 | F26: =IF($D26="",'NPV PT'!E26,'NPV PT'!E26*(1+$D26)) -> 0 | G26: =IF($D26="",'NPV PT'!F26,'NPV PT'!F26*(1+$D26)) -> 0 | H26: =IF($D26="",'NPV PT'!G26,'NPV PT'!G26*(1+$D26)) -> 0 | I26: =IF($D26="",'NPV PT'!H26,'NPV PT'!H26*(1+$D26)) -> 0 | J26: =IF($D26="",'NPV PT'!I26,'NPV PT'!I26*(1+$D26)) -> 0 | K26: =IF($D26="",'NPV PT'!J26,'NPV PT'!J26*(1+$D26)) -> 0 | L26: =IF($D26="",'NPV PT'!K26,'NPV PT'!K26*(1+$D26)) -> 0 | ... O26: =IF($D26="",'NPV PT'!N26,'NPV PT'!N26*(1+$D26)) -> 0
B27: CFC (TCC) | C27: =VLOOKUP($C$2,countries!C:F,4,0) -> MYR | E27: =IF($D27="",'NPV PT'!D27,'NPV PT'!D27*(1+$D27)) -> 0 | F27: =IF($D27="",'NPV PT'!E27,'NPV PT'!E27*(1+$D27)) -> 0 | G27: =IF($D27="",'NPV PT'!F27,'NPV PT'!F27*(1+$D27)) -> 0 | H27: =IF($D27="",'NPV PT'!G27,'NPV PT'!G27*(1+$D27)) -> 0 | I27: =IF($D27="",'NPV PT'!H27,'NPV PT'!H27*(1+$D27)) -> 0 | J27: =IF($D27="",'NPV PT'!I27,'NPV PT'!I27*(1+$D27)) -> 0 | K27: =IF($D27="",'NPV PT'!J27,'NPV PT'!J27*(1+$D27)) -> 0 | L27: =IF($D27="",'NPV PT'!K27,'NPV PT'!K27*(1+$D27)) -> 0 | ... O27: =IF($D27="",'NPV PT'!N27,'NPV PT'!N27*(1+$D27)) -> 0
B28: Marketing costs (TCC) | C28: =VLOOKUP($C$2,countries!C:F,4,0) -> MYR | E28: =IF($D28="",'NPV PT'!D28,'NPV PT'!D28*(1+$D28)) -> -400000 | F28: =IF($D28="",'NPV PT'!E28,'NPV PT'!E28*(1+$D28)) -> 0 | G28: =IF($D28="",'NPV PT'!F28,'NPV PT'!F28*(1+$D28)) -> 0 | H28: =IF($D28="",'NPV PT'!G28,'NPV PT'!G28*(1+$D28)) -> 0 | I28: =IF($D28="",'NPV PT'!H28,'NPV PT'!H28*(1+$D28)) -> 0 | J28: =IF($D28="",'NPV PT'!I28,'NPV PT'!I28*(1+$D28)) -> 0 | K28: =IF($D28="",'NPV PT'!J28,'NPV PT'!J28*(1+$D28)) -> 0 | L28: =IF($D28="",'NPV PT'!K28,'NPV PT'!K28*(1+$D28)) -> 0 | ... O28: =IF($D28="",'NPV PT'!N28,'NPV PT'!N28*(1+$D28)) -> 0
B29: ASP | C29: =VLOOKUP($C$2,countries!C:F,4,0) -> MYR | E29: =IF($D29="",'NPV PT'!D29,'NPV PT'!D29*(1+$D29)) -> 0 | F29: =IF($D29="",'NPV PT'!E29,'NPV PT'!E29*(1+$D29)) -> 0 | G29: =IF($D29="",'NPV PT'!F29,'NPV PT'!F29*(1+$D29)) -> 0 | H29: =IF($D29="",'NPV PT'!G29,'NPV PT'!G29*(1+$D29)) -> 0 | I29: =IF($D29="",'NPV PT'!H29,'NPV PT'!H29*(1+$D29)) -> 0 | J29: =IF($D29="",'NPV PT'!I29,'NPV PT'!I29*(1+$D29)) -> 0 | K29: =IF($D29="",'NPV PT'!J29,'NPV PT'!J29*(1+$D29)) -> 0 | L29: =IF($D29="",'NPV PT'!K29,'NPV PT'!K29*(1+$D29)) -> 0 | ... O29: =IF($D29="",'NPV PT'!N29,'NPV PT'!N29*(1+$D29)) -> 0
B30: Write-offs (COGS - GM) | C30: =VLOOKUP($C$2,countries!C:F,4,0) -> MYR | E30: =IF($D30="",'NPV PT'!D30,'NPV PT'!D30*(1+$D30)) -> 0 | F30: =IF($D30="",'NPV PT'!E30,'NPV PT'!E30*(1+$D30)) -> 0 | G30: =IF($D30="",'NPV PT'!F30,'NPV PT'!F30*(1+$D30)) -> 0 | H30: =IF($D30="",'NPV PT'!G30,'NPV PT'!G30*(1+$D30)) -> 0 | I30: =IF($D30="",'NPV PT'!H30,'NPV PT'!H30*(1+$D30)) -> 0 | J30: =IF($D30="",'NPV PT'!I30,'NPV PT'!I30*(1+$D30)) -> 0 | K30: =IF($D30="",'NPV PT'!J30,'NPV PT'!J30*(1+$D30)) -> 0 | L30: =IF($D30="",'NPV PT'!K30,'NPV PT'!K30*(1+$D30)) -> 0 | ... O30: =IF($D30="",'NPV PT'!N30,'NPV PT'!N30*(1+$D30)) -> 0
B31: Other Income | C31: =VLOOKUP($C$2,countries!C:F,4,0) -> MYR | E31: =IF($D31="",'NPV PT'!D31,'NPV PT'!D31*(1+$D31)) -> 0 | F31: =IF($D31="",'NPV PT'!E31,'NPV PT'!E31*(1+$D31)) -> 0 | G31: =IF($D31="",'NPV PT'!F31,'NPV PT'!F31*(1+$D31)) -> 0 | H31: =IF($D31="",'NPV PT'!G31,'NPV PT'!G31*(1+$D31)) -> 0 | I31: =IF($D31="",'NPV PT'!H31,'NPV PT'!H31*(1+$D31)) -> 0 | J31: =IF($D31="",'NPV PT'!I31,'NPV PT'!I31*(1+$D31)) -> 0 | K31: =IF($D31="",'NPV PT'!J31,'NPV PT'!J31*(1+$D31)) -> 0 | L31: =IF($D31="",'NPV PT'!K31,'NPV PT'!K31*(1+$D31)) -> 0 | ... O31: =IF($D31="",'NPV PT'!N31,'NPV PT'!N31*(1+$D31)) -> 0
B32: GSC Savings/Costs (GM) - RM COGS | C32: =VLOOKUP($C$2,countries!C:F,4,0) -> MYR | E32: =IF($D32="",'NPV PT'!D32,'NPV PT'!D32*(1+$D32)) -> 0 | F32: =IF($D32="",'NPV PT'!E32,'NPV PT'!E32*(1+$D32)) -> 0 | G32: =IF($D32="",'NPV PT'!F32,'NPV PT'!F32*(1+$D32)) -> 0 | H32: =IF($D32="",'NPV PT'!G32,'NPV PT'!G32*(1+$D32)) -> 0 | I32: =IF($D32="",'NPV PT'!H32,'NPV PT'!H32*(1+$D32)) -> 0 | J32: =IF($D32="",'NPV PT'!I32,'NPV PT'!I32*(1+$D32)) -> 0 | K32: =IF($D32="",'NPV PT'!J32,'NPV PT'!J32*(1+$D32)) -> 0 | L32: =IF($D32="",'NPV PT'!K32,'NPV PT'!K32*(1+$D32)) -> 0 | ... O32: =IF($D32="",'NPV PT'!N32,'NPV PT'!N32*(1+$D32)) -> 0
B33: GSC Savings/Costs (TCC) - Manufacturing | C33: =VLOOKUP($C$2,countries!C:F,4,0) -> MYR | E33: =IF($D33="",'NPV PT'!D33,'NPV PT'!D33*(1+$D33)) -> 0 | F33: =IF($D33="",'NPV PT'!E33,'NPV PT'!E33*(1+$D33)) -> 0 | G33: =IF($D33="",'NPV PT'!F33,'NPV PT'!F33*(1+$D33)) -> 0 | H33: =IF($D33="",'NPV PT'!G33,'NPV PT'!G33*(1+$D33)) -> 0 | I33: =IF($D33="",'NPV PT'!H33,'NPV PT'!H33*(1+$D33)) -> 0 | J33: =IF($D33="",'NPV PT'!I33,'NPV PT'!I33*(1+$D33)) -> 0 | K33: =IF($D33="",'NPV PT'!J33,'NPV PT'!J33*(1+$D33)) -> 0 | L33: =IF($D33="",'NPV PT'!K33,'NPV PT'!K33*(1+$D33)) -> 0 | ... O33: =IF($D33="",'NPV PT'!N33,'NPV PT'!N33*(1+$D33)) -> 0
B34: GSC Savings/Costs (TCC) - BU Support | C34: =VLOOKUP($C$2,countries!C:F,4,0) -> MYR | E34: =IF($D34="",'NPV PT'!D34,'NPV PT'!D34*(1+$D34)) -> 0 | F34: =IF($D34="",'NPV PT'!E34,'NPV PT'!E34*(1+$D34)) -> 0 | G34: =IF($D34="",'NPV PT'!F34,'NPV PT'!F34*(1+$D34)) -> 0 | H34: =IF($D34="",'NPV PT'!G34,'NPV PT'!G34*(1+$D34)) -> 0 | I34: =IF($D34="",'NPV PT'!H34,'NPV PT'!H34*(1+$D34)) -> 0 | J34: =IF($D34="",'NPV PT'!I34,'NPV PT'!I34*(1+$D34)) -> 0 | K34: =IF($D34="",'NPV PT'!J34,'NPV PT'!J34*(1+$D34)) -> 0 | L34: =IF($D34="",'NPV PT'!K34,'NPV PT'!K34*(1+$D34)) -> 0 | ... O34: =IF($D34="",'NPV PT'!N34,'NPV PT'!N34*(1+$D34)) -> 0
B35: GSC Savings/Costs (ACC) - Primary Logistics | C35: =VLOOKUP($C$2,countries!C:F,4,0) -> MYR | E35: =IF($D35="",'NPV PT'!D35,'NPV PT'!D35*(1+$D35)) -> 0 | F35: =IF($D35="",'NPV PT'!E35,'NPV PT'!E35*(1+$D35)) -> 0 | G35: =IF($D35="",'NPV PT'!F35,'NPV PT'!F35*(1+$D35)) -> 0 | H35: =IF($D35="",'NPV PT'!G35,'NPV PT'!G35*(1+$D35)) -> 0 | I35: =IF($D35="",'NPV PT'!H35,'NPV PT'!H35*(1+$D35)) -> 0 | J35: =IF($D35="",'NPV PT'!I35,'NPV PT'!I35*(1+$D35)) -> 0 | K35: =IF($D35="",'NPV PT'!J35,'NPV PT'!J35*(1+$D35)) -> 0 | L35: =IF($D35="",'NPV PT'!K35,'NPV PT'!K35*(1+$D35)) -> 0 | ... O35: =IF($D35="",'NPV PT'!N35,'NPV PT'!N35*(1+$D35)) -> 0
B36: GSC Savings/Costs (ACC) - S&H | C36: =VLOOKUP($C$2,countries!C:F,4,0) -> MYR | E36: =IF($D36="",'NPV PT'!D36,'NPV PT'!D36*(1+$D36)) -> 0 | F36: =IF($D36="",'NPV PT'!E36,'NPV PT'!E36*(1+$D36)) -> 0 | G36: =IF($D36="",'NPV PT'!F36,'NPV PT'!F36*(1+$D36)) -> 0 | H36: =IF($D36="",'NPV PT'!G36,'NPV PT'!G36*(1+$D36)) -> 0 | I36: =IF($D36="",'NPV PT'!H36,'NPV PT'!H36*(1+$D36)) -> 0 | J36: =IF($D36="",'NPV PT'!I36,'NPV PT'!I36*(1+$D36)) -> 0 | K36: =IF($D36="",'NPV PT'!J36,'NPV PT'!J36*(1+$D36)) -> 0 | L36: =IF($D36="",'NPV PT'!K36,'NPV PT'!K36*(1+$D36)) -> 0 | ... O36: =IF($D36="",'NPV PT'!N36,'NPV PT'!N36*(1+$D36)) -> 0
... B38: GBS cost savings (TCC) | C38: =VLOOKUP($C$2,countries!C:F,4,0) -> MYR | E38: =IF($D38="",'NPV PT'!D38,'NPV PT'!D38*(1+$D38)) -> 0 | F38: =IF($D38="",'NPV PT'!E38,'NPV PT'!E38*(1+$D38)) -> 0 | G38: =IF($D38="",'NPV PT'!F38,'NPV PT'!F38*(1+$D38)) -> 0 | H38: =IF($D38="",'NPV PT'!G38,'NPV PT'!G38*(1+$D38)) -> 0 | I38: =IF($D38="",'NPV PT'!H38,'NPV PT'!H38*(1+$D38)) -> 0 | J38: =IF($D38="",'NPV PT'!I38,'NPV PT'!I38*(1+$D38)) -> 0 | K38: =IF($D38="",'NPV PT'!J38,'NPV PT'!J38*(1+$D38)) -> 0 | L38: =IF($D38="",'NPV PT'!K38,'NPV PT'!K38*(1+$D38)) -> 0 | ... O38: =IF($D38="",'NPV PT'!N38,'NPV PT'!N38*(1+$D38)) -> 0
B39: Project Revex (Implementation costs) | C39: =VLOOKUP($C$2,countries!C:F,4,0) -> MYR | D39: 0.1 | E39: =IF($D39="",'NPV PT'!D39,'NPV PT'!D39*(1+$D39)) -> 0 | F39: =IF($D39="",'NPV PT'!E39,'NPV PT'!E39*(1+$D39)) -> 0 | G39: =IF($D39="",'NPV PT'!F39,'NPV PT'!F39*(1+$D39)) -> 0 | H39: =IF($D39="",'NPV PT'!G39,'NPV PT'!G39*(1+$D39)) -> 0 | I39: =IF($D39="",'NPV PT'!H39,'NPV PT'!H39*(1+$D39)) -> 0 | J39: =IF($D39="",'NPV PT'!I39,'NPV PT'!I39*(1+$D39)) -> 0 | K39: =IF($D39="",'NPV PT'!J39,'NPV PT'!J39*(1+$D39)) -> 0 | L39: =IF($D39="",'NPV PT'!K39,'NPV PT'!K39*(1+$D39)) -> 0 | ... O39: =IF($D39="",'NPV PT'!N39,'NPV PT'!N39*(1+$D39)) -> 0
B40: Depreciation | C40: =VLOOKUP($C$2,countries!C:F,4,0) -> MYR | E40: =SUM('Capex&Depr'!F54:F63) -> 0 | F40: =SUM('Capex&Depr'!G54:G63) -> -498960 | G40: =SUM('Capex&Depr'!H54:H63) -> -498960 | H40: =SUM('Capex&Depr'!I54:I63) -> -498960 | I40: =SUM('Capex&Depr'!J54:J63) -> -498960 | J40: =SUM('Capex&Depr'!K54:K63) -> -498960 | K40: =SUM('Capex&Depr'!L54:L63) -> 0 | L40: =SUM('Capex&Depr'!M54:M63) -> 0 | ... O40: =SUM('Capex&Depr'!P54:P63) -> 0
B41: Impairment | C41: =VLOOKUP($C$2,countries!C:F,4,0) -> MYR | E41: =IF($D41="",'NPV PT'!D41,'NPV PT'!D41*(1+$D41)) -> 0 | F41: =IF($D41="",'NPV PT'!E41,'NPV PT'!E41*(1+$D41)) -> 0 | G41: =IF($D41="",'NPV PT'!F41,'NPV PT'!F41*(1+$D41)) -> 0 | H41: =IF($D41="",'NPV PT'!G41,'NPV PT'!G41*(1+$D41)) -> 0 | I41: =IF($D41="",'NPV PT'!H41,'NPV PT'!H41*(1+$D41)) -> 0 | J41: =IF($D41="",'NPV PT'!I41,'NPV PT'!I41*(1+$D41)) -> 0 | K41: =IF($D41="",'NPV PT'!J41,'NPV PT'!J41*(1+$D41)) -> 0 | L41: =IF($D41="",'NPV PT'!K41,'NPV PT'!K41*(1+$D41)) -> 0 | ... O41: =IF($D41="",'NPV PT'!N41,'NPV PT'!N41*(1+$D41)) -> 0
B42: Remediation & Dismantling Costs | C42: =VLOOKUP($C$2,countries!C:F,4,0) -> MYR | D42: 0.1 | E42: =IF($D42="",'NPV PT'!D42,'NPV PT'!D42*(1+$D42)) -> 0 | F42: =IF($D42="",'NPV PT'!E42,'NPV PT'!E42*(1+$D42)) -> 0 | G42: =IF($D42="",'NPV PT'!F42,'NPV PT'!F42*(1+$D42)) -> 0 | H42: =IF($D42="",'NPV PT'!G42,'NPV PT'!G42*(1+$D42)) -> 0 | I42: =IF($D42="",'NPV PT'!H42,'NPV PT'!H42*(1+$D42)) -> 0 | J42: =IF($D42="",'NPV PT'!I42,'NPV PT'!I42*(1+$D42)) -> 0 | K42: =IF($D42="",'NPV PT'!J42,'NPV PT'!J42*(1+$D42)) -> 0 | L42: =IF($D42="",'NPV PT'!K42,'NPV PT'!K42*(1+$D42)) -> 0 | ... O42: =IF($D42="",'NPV PT'!N42,'NPV PT'!N42*(1+$D42)) -> 0
B43: Ratex accrued | C43: =VLOOKUP($C$2,countries!C:F,4,0) -> MYR | D43: 0.1 | E43: =IF($D43="",'NPV PT'!D43,'NPV PT'!D43*(1+$D43)) -> 0 | F43: =IF($D43="",'NPV PT'!E43,'NPV PT'!E43*(1+$D43)) -> 0 | G43: =IF($D43="",'NPV PT'!F43,'NPV PT'!F43*(1+$D43)) -> 0 | H43: =IF($D43="",'NPV PT'!G43,'NPV PT'!G43*(1+$D43)) -> 0 | I43: =IF($D43="",'NPV PT'!H43,'NPV PT'!H43*(1+$D43)) -> 0 | J43: =IF($D43="",'NPV PT'!I43,'NPV PT'!I43*(1+$D43)) -> 0 | K43: =IF($D43="",'NPV PT'!J43,'NPV PT'!J43*(1+$D43)) -> 0 | L43: =IF($D43="",'NPV PT'!K43,'NPV PT'!K43*(1+$D43)) -> 0 | ... O43: =IF($D43="",'NPV PT'!N43,'NPV PT'!N43*(1+$D43)) -> 0
B44: Net Profit | C44: =VLOOKUP($C$2,countries!C:F,4,0) -> MYR | E44: =SUM(E23:E43) -> -400000 | F44: =SUM(F23:F43) -> 5637883.5 | G44: =SUM(G23:G43) -> 5324918.1 | H44: =SUM(H23:H43) -> 5134417.4 | I44: =SUM(I23:I43) -> 4998345.5 | J44: =SUM(J23:J43) -> 4889488 | K44: =SUM(K23:K43) -> 0 | L44: =SUM(L23:L43) -> 0 | ... O44: =SUM(O23:O43) -> 0
B45: Interest | C45: =VLOOKUP($C$2,countries!C:F,4,0) -> MYR | E45: 0 | F45: 0 | G45: 0 | H45: 0 | I45: 0 | J45: 0 | K45: 0 | L45: 0 | M45: 0 | N45: 0 | O45: 0
B46: Net Profit After interest | C46: =VLOOKUP($C$2,countries!C:F,4,0) -> MYR | E46: =+E45+E44 -> -400000 | F46: =SUM(F44:F45) -> 5637883.5 | G46: =SUM(G44:G45) -> 5324918.1 | H46: =SUM(H44:H45) -> 5134417.4 | I46: =SUM(I44:I45) -> 4998345.5 | J46: =SUM(J44:J45) -> 4889488 | K46: =SUM(K44:K45) -> 0 | L46: =SUM(L44:L45) -> 0 | M46: =SUM(M44:M45) -> 0 | ... O46: =SUM(O44:O45) -> 0
...

Sheet Chart1 CashFlow
A1: GIAAP Finance Charts Template | H1: How to use
A3: Chart 1 | B3: Cash Flow Components
A5: Parameter | B5: Annual $m
A7: Input Data | B7: Add, remove or modify rows as required to show cashflow.
A8: Year | B8: ='NPV PT'!D10 -> 2025 | C8: =B8+1 -> 2026 | D8: =C8+1 -> 2027 | E8: =D8+1 -> 2028 | F8: =E8+1 -> 2029 | G8: =F8+1 -> 2030 | H8: =G8+1 -> 2031 | I8: =H8+1 -> 2032 | J8: =I8+1 -> 2033 | ... Q8: =P8+1 -> 2040
A9: Cash Capex | B9: ='NPV PT'!D92/1000000 -> -0.29745902 | C9: ='NPV PT'!E92/1000000 -> 0 | D9: ='NPV PT'!F92/1000000 -> 0 | E9: ='NPV PT'!G92/1000000 -> 0 | F9: ='NPV PT'!H92/1000000 -> 0 | G9: ='NPV PT'!I92/1000000 -> 0 | H9: ='NPV PT'!J92/1000000 -> 0 | I9: ='NPV PT'!K92/1000000 -> 0 | ... L9: ='NPV PT'!N92/1000000 -> 0 | M9: =[64]NPV!O59 -> 0 | N9: =[64]NPV!P59 -> 0 | O9: =[64]NPV!Q59 -> 0 | P9: =[64]NPV!R59 -> 0 | Q9: =[64]NPV!S59 -> 0 | S9: Capex
A10: Ratex | B10: ='NPV PT'!D95/1000000 -> 0 | C10: ='NPV PT'!E95/1000000 -> 0 | D10: ='NPV PT'!F95/1000000 -> 0 | E10: ='NPV PT'!G95/1000000 -> 0 | F10: ='NPV PT'!H95/1000000 -> 0 | G10: ='NPV PT'!I95/1000000 -> 0 | H10: ='NPV PT'!J95/1000000 -> 0 | I10: ='NPV PT'!K95/1000000 -> 0 | ... L10: ='NPV PT'!N95/1000000 -> 0 | M10: =[64]NPV!O60 -> 0 | N10: =[64]NPV!P60 -> 0 | O10: =[64]NPV!Q60 -> 0 | P10: =[64]NPV!R60 -> 0 | Q10: =[64]NPV!S60 -> 0 | S10: Capex Creditors
A11: Revex (incl Remediation) | B11: =('NPV PT'!D94+'NPV PT'!D93)/1000000 -> 0 | C11: =('NPV PT'!E94+'NPV PT'!E93)/1000000 -> 0 | D11: =('NPV PT'!F94+'NPV PT'!F93)/1000000 -> 0 | E11: =('NPV PT'!G94+'NPV PT'!G93)/1000000 -> 0 | F11: =('NPV PT'!H94+'NPV PT'!H93)/1000000 -> 0 | G11: =('NPV PT'!I94+'NPV PT'!I93)/1000000 -> 0 | H11: =('NPV PT'!J94+'NPV PT'!J93)/1000000 -> 0 | I11: =('NPV PT'!K94+'NPV PT'!K93)/1000000 -> 0 | ... L11: =('NPV PT'!N94+'NPV PT'!N93)/1000000 -> 0 | M11: =[64]NPV!O61 -> 0 | N11: =[64]NPV!P61 -> 0 | O11: =[64]NPV!Q61 -> 0 | P11: =[64]NPV!R61 -> 0 | Q11: =[64]NPV!S61 -> 0 | S11: Ratex
A12: GM+TCC | B12: ='NPV PT'!D97/1000000+'NPV PT'!D98/1000000 -> -0.053503185 | C12: ='NPV PT'!E97/1000000+'NPV PT'!E98/1000000 -> 0.85725308 | D12: ='NPV PT'!F97/1000000+'NPV PT'!F98/1000000 -> 0.85725308 | E12: ='NPV PT'!G97/1000000+'NPV PT'!G98/1000000 -> 0.85725308 | F12: ='NPV PT'!H97/1000000+'NPV PT'!H98/1000000 -> 0.85725308 | G12: ='NPV PT'!I97/1000000+'NPV PT'!I98/1000000 -> 0.85725308 | H12: ='NPV PT'!J97/1000000+'NPV PT'!J98/1000000 -> 0 | I12: ='NPV PT'!K97/1000000+'NPV PT'!K98/1000000 -> 0 | ... L12: ='NPV PT'!N97/1000000+'NPV PT'!N98/1000000 -> 0 | M12: =[64]NPV!O62 -> 0 | N12: =[64]NPV!P62 -> 0 | O12: =[64]NPV!Q62 -> 0 | P12: =[64]NPV!R62 -> 0 | Q12: =[64]NPV!S62 -> 0 | S12: Ratex Creditors
A13: Tax | B13: =('NPV PT'!D47/'NPV PT'!D12+'NPV PT'!D55/'NPV PT'!D12)/1000000 -> 0.020382166 | C13: =('NPV PT'!E47/'NPV PT'!E12+'NPV PT'!E55/'NPV PT'!E12)/1000000 -> -0.30100382 | D13: =('NPV PT'!F47/'NPV PT'!F12+'NPV PT'!F55/'NPV PT'!F12)/1000000 -> -0.2996298 | E13: =('NPV PT'!G47/'NPV PT'!G12+'NPV PT'!G55/'NPV PT'!G12)/1000000 -> -0.29871869 | F13: =('NPV PT'!H47/'NPV PT'!H12+'NPV PT'!H55/'NPV PT'!H12)/1000000 -> -0.29802924 | G13: =('NPV PT'!I47/'NPV PT'!I12+'NPV PT'!I55/'NPV PT'!I12)/1000000 -> -0.2974526 | H13: =('NPV PT'!J47/'NPV PT'!J12+'NPV PT'!J55/'NPV PT'!J12)/1000000 -> 0 | I13: =('NPV PT'!K47/'NPV PT'!K12+'NPV PT'!K55/'NPV PT'!K12)/1000000 -> 0 | ... L13: =('NPV PT'!N47/'NPV PT'!N12+'NPV PT'!N55/'NPV PT'!N12)/1000000 -> 0 | M13: =[64]NPV!O63 -> 0 | N13: =[64]NPV!P63 -> 0 | O13: =[64]NPV!Q63 -> 0 | P13: =[64]NPV!R63 -> 0 | Q13: =[64]NPV!S63 -> 0 | S13: Revex (incl Remediation)
A14: Working Capital Change | B14: =(SUM('NPV PT'!D57:D63)/'NPV PT'!D12)/1000000 -> 0 | C14: =(SUM('NPV PT'!E57:E63)/'NPV PT'!E12)/1000000 -> 0 | D14: =(SUM('NPV PT'!F57:F63)/'NPV PT'!F12)/1000000 -> 0 | E14: =(SUM('NPV PT'!G57:G63)/'NPV PT'!G12)/1000000 -> 0 | F14: =(SUM('NPV PT'!H57:H63)/'NPV PT'!H12)/1000000 -> 0 | G14: =(SUM('NPV PT'!I57:I63)/'NPV PT'!I12)/1000000 -> 0 | H14: =(SUM('NPV PT'!J57:J63)/'NPV PT'!J12)/1000000 -> 0 | I14: =(SUM('NPV PT'!K57:K63)/'NPV PT'!K12)/1000000 -> 0 | ... L14: =(SUM('NPV PT'!N57:N63)/'NPV PT'!N12)/1000000 -> 0 | M14: -1.800926 | N14: -1.8474208 | O14: -1.8945361 | P14: -6.7976573 | Q14: =('[65]FM-usd'!U39)/1000000 -> 0 | S14: Tax
A15: Disp Gains & Other cash | B15: =B16-SUM(B9:B14) -> -0.031422505 | C15: =C16-SUM(C9:C14) -> 0.11137141 | D15: =D16-SUM(D9:D14) -> 0.11086303 | E15: =E16-SUM(E9:E14) -> 0.11052592 | F15: =F16-SUM(F9:F14) -> 0.11027082 | G15: =G16-SUM(G9:G14) -> 0.11005746 | H15: =H16-SUM(H9:H14) -> 0 | I15: =I16-SUM(I9:I14) -> 0 | ... L15: =L16-SUM(L9:L14) -> 0 | M15: =[64]NPV!O65 -> 0 | N15: =[64]NPV!P65 -> 0 | O15: =[64]NPV!Q65 -> 0 | P15: =[64]NPV!R65 -> 0 | Q15: =[64]NPV!S65 -> 0 | S15: Working Capital Change
A16: Cashflow | B16: ='NPV PT'!D66 -> -0.36200255 | C16: ='NPV PT'!E66 -> 0.66762068 | D16: ='NPV PT'!F66 -> 0.66848631 | E16: ='NPV PT'!G66 -> 0.66906031 | F16: ='NPV PT'!H66 -> 0.66949466 | G16: ='NPV PT'!I66 -> 0.66985794 | H16: ='NPV PT'!J66 -> 0 | I16: ='NPV PT'!K66 -> 0 | ... L16: ='NPV PT'!N66 -> 0 | M16: =[64]NPV!O66 -> 0 | N16: =[64]NPV!P66 -> 0 | O16: =[64]NPV!Q66 -> 0 | P16: =[64]NPV!R66 -> 0 | Q16: =[64]NPV!S66 -> 0
A17: Disc Cashflow | B17: ='NPV PT'!D67 -> -0.34996107 | C17: ='NPV PT'!E67 -> 0.60318997 | D17: ='NPV PT'!F67 -> 0.56445987 | E17: ='NPV PT'!G67 -> 0.52798556 | F17: ='NPV PT'!H67 -> 0.49376479 | G17: ='NPV PT'!I67 -> 0.46171282 | H17: ='NPV PT'!J67 -> 0 | I17: ='NPV PT'!K67 -> 0 | ... L17: ='NPV PT'!N67 -> 0 | M17: =[64]NPV!O67 -> 0 | N17: =[64]NPV!P67 -> 0 | O17: =[64]NPV!Q67 -> 0 | P17: =[64]NPV!R67 -> 0 | Q17: =[64]NPV!S67 -> 0
A18: Cum Cashflow | B18: =B17 -> -0.34996107 | C18: =B18+C17 -> 0.2532289 | D18: =C18+D17 -> 0.81768877 | E18: =D18+E17 -> 1.3456743 | F18: =E18+F17 -> 1.8394391 | G18: =F18+G17 -> 2.3011519 | H18: =G18+H17 -> 2.3011519 | I18: =H18+I17 -> 2.3011519 | J18: =I18+J17 -> 2.3011519 | ... L18: =K18+L17 -> 2.3011519 | M18: 23.272073 | N18: 25.110377 | O18: 26.97858 | P18: 26.643385 | Q18: =Q16+P18 -> 26.643385
A19: Cum DCF | B19: =B18 -> -0.34996107 | C19: =C18 -> 0.2532289 | D19: =D18 -> 0.81768877 | E19: =E18 -> 1.3456743 | F19: =F18 -> 1.8394391 | G19: =G18 -> 2.3011519 | H19: =H18 -> 2.3011519 | I19: =I18 -> 2.3011519 | ... L19: =L18 -> 2.3011519 | M19: 14.252951 | N19: 14.955409 | O19: 15.616412 | P19: 15.5066 | Q19: =Q17+P19 -> 15.5066
A21: Chart

Sheet Chart2 Tornado
A1: GIAAP Finance Charts Template | H1: How to use | O1: Inner workings
A3: Chart 2 | B3: Project Sensitivities | O3: ="Central Case NPV "&TEXT(B7,"$#")&"m, IRR "&TEXT(D7,"#%") -> Central Case NPV $1m, IRR 31%
A5: Input Data
A6: Parameter | B6: NPV $m | D6: IRR %
A7: Central Case | B7: 0.71 | D7: 0.31 | O7: Chart Data | V7: Chart Labels
A8: Sensitivity Cases | B8: Upside | C8: Downside | D8: Upside | E8: Downside | F8: Error Chk | O8: Series | P8: blank + | Q8: blank - | R8: red + | S8: green - | T8: red - | U8: green + | V8: red + | W8: green - | X8: red - | Y8: green +
A9: Volume growth @ 70% | F9: {=IF(AND(ISNUMBER(B9:C9)),IF(OR($B$7<C9,$D$7<E9),"Downside must be < Central",IF(OR($B$7>B9,$D$7>D9),"Upside must be > Central","OK")),"Enter numeric data")} -> Enter numeric data | O9: =A9 -> Volume growth @ 70% | P9: =MAX(MIN(B9:C9),0) -> 0 | Q9: =MIN(MAX(B9:C9),0) -> 0 | R9: =IF(C9,IF($B$7<0,,MIN($B$7-C9,$B$7)),) -> 0 | S9: =IF(B9,IF($B$7>0,,MAX($B$7-B9,$B$7)),) -> 0 | T9: =IF(C9,C9-$B$7+R9,) -> 0 | U9: =IF(B9,B9-$B$7+S9,) -> 0 | V9: =IF(T9,,IF(R9,TEXT(C9,"#")&IF(ISNUMBER(E9),TEXT(E9,", #%"),", "&E9),)) -> 0 | W9: =IF(U9,,IF(S9,TEXT(B9,"#")&TEXT(D9,", #%"),)) -> 0 | X9: =IF(T9,TEXT(C9,"#")&IF(ISNUMBER(E9),TEXT(E9,", #%"),", "&E9),) -> 0 | Y9: =IF(U9,TEXT(B9,"#")&TEXT(D9,", #%"),) -> 0
C10: 8 | F10: {=IF(AND(ISNUMBER(B10:C10)),IF(OR($B$7<C10,$D$7<E10),"Downside must be < Central",IF(OR($B$7>B10,$D$7>D10),"Upside must be > Central","OK")),"Enter numeric data")} -> Enter numeric data | O10: =A10 -> 0 | P10: =MAX(MIN(B10:C10),0) -> 8 | Q10: =MIN(MAX(B10:C10),0) -> 0 | R10: =IF(C10,IF($B$7<0,,MIN($B$7-C10,$B$7)),) -> -7.29 | S10: =IF(B10,IF($B$7>0,,MAX($B$7-B10,$B$7)),) -> 0 | T10: =IF(C10,C10-$B$7+R10,) -> 0 | U10: =IF(B10,B10-$B$7+S10,) -> 0 | V10: =IF(T10,,IF(R10,TEXT(C10,"#")&IF(ISNUMBER(E10),TEXT(E10,", #%"),", "&E10),)) -> 8, | W10: =IF(U10,,IF(S10,TEXT(B10,"#")&TEXT(D10,", #%"),)) -> 0 | X10: =IF(T10,TEXT(C10,"#")&IF(ISNUMBER(E10),TEXT(E10,", #%"),", "&E10),) -> 0 | Y10: =IF(U10,TEXT(B10,"#")&TEXT(D10,", #%"),) -> 0
C11: 7 | F11: {=IF(AND(ISNUMBER(B11:C11)),IF(OR($B$7<C11,$D$7<E11),"Downside must be < Central",IF(OR($B$7>B11,$D$7>D11),"Upside must be > Central","OK")),"Enter numeric data")} -> Enter numeric data | O11: =A11 -> 0 | P11: =MAX(MIN(B11:C11),0) -> 7 | Q11: =MIN(MAX(B11:C11),0) -> 0 | R11: =IF(C11,IF($B$7<0,,MIN($B$7-C11,$B$7)),) -> -6.29 | S11: =IF(B11,IF($B$7>0,,MAX($B$7-B11,$B$7)),) -> 0 | T11: =IF(C11,C11-$B$7+R11,) -> 0 | U11: =IF(B11,B11-$B$7+S11,) -> 0 | V11: =IF(T11,,IF(R11,TEXT(C11,"#")&IF(ISNUMBER(E11),TEXT(E11,", #%"),", "&E11),)) -> 7, | W11: =IF(U11,,IF(S11,TEXT(B11,"#")&TEXT(D11,", #%"),)) -> 0 | X11: =IF(T11,TEXT(C11,"#")&IF(ISNUMBER(E11),TEXT(E11,", #%"),", "&E11),) -> 0 | Y11: =IF(U11,TEXT(B11,"#")&TEXT(D11,", #%"),) -> 0
C12: 6 | F12: {=IF(AND(ISNUMBER(B12:C12)),IF(OR($B$7<C12,$D$7<E12),"Downside must be < Central",IF(OR($B$7>B12,$D$7>D12),"Upside must be > Central","OK")),"Enter numeric data")} -> Enter numeric data | O12: =A12 -> 0 | P12: =MAX(MIN(B12:C12),0) -> 6 | Q12: =MIN(MAX(B12:C12),0) -> 0 | R12: =IF(C12,IF($B$7<0,,MIN($B$7-C12,$B$7)),) -> -5.29 | S12: =IF(B12,IF($B$7>0,,MAX($B$7-B12,$B$7)),) -> 0 | T12: =IF(C12,C12-$B$7+R12,) -> 0 | U12: =IF(B12,B12-$B$7+S12,) -> 0 | V12: =IF(T12,,IF(R12,TEXT(C12,"#")&IF(ISNUMBER(E12),TEXT(E12,", #%"),", "&E12),)) -> 6, | W12: =IF(U12,,IF(S12,TEXT(B12,"#")&TEXT(D12,", #%"),)) -> 0 | X12: =IF(T12,TEXT(C12,"#")&IF(ISNUMBER(E12),TEXT(E12,", #%"),", "&E12),) -> 0 | Y12: =IF(U12,TEXT(B12,"#")&TEXT(D12,", #%"),) -> 0
C13: 7 | F13: {=IF(AND(ISNUMBER(B13:C13)),IF(OR($B$7<C13,$D$7<E13),"Downside must be < Central",IF(OR($B$7>B13,$D$7>D13),"Upside must be > Central","OK")),"Enter numeric data")} -> Enter numeric data | O13: =A13 -> 0 | P13: =MAX(MIN(B13:C13),0) -> 7 | Q13: =MIN(MAX(B13:C13),0) -> 0 | R13: =IF(C13,IF($B$7<0,,MIN($B$7-C13,$B$7)),) -> -6.29 | S13: =IF(B13,IF($B$7>0,,MAX($B$7-B13,$B$7)),) -> 0 | T13: =IF(C13,C13-$B$7+R13,) -> 0 | U13: =IF(B13,B13-$B$7+S13,) -> 0 | V13: =IF(T13,,IF(R13,TEXT(C13,"#")&IF(ISNUMBER(E13),TEXT(E13,", #%"),", "&E13),)) -> 7, | W13: =IF(U13,,IF(S13,TEXT(B13,"#")&TEXT(D13,", #%"),)) -> 0 | X13: =IF(T13,TEXT(C13,"#")&IF(ISNUMBER(E13),TEXT(E13,", #%"),", "&E13),) -> 0 | Y13: =IF(U13,TEXT(B13,"#")&TEXT(D13,", #%"),) -> 0
C14: 8 | F14: {=IF(AND(ISNUMBER(B14:C14)),IF(OR($B$7<C14,$D$7<E14),"Downside must be < Central",IF(OR($B$7>B14,$D$7>D14),"Upside must be > Central","OK")),"Enter numeric data")} -> Enter numeric data | O14: =A14 -> 0 | P14: =MAX(MIN(B14:C14),0) -> 8 | Q14: =MIN(MAX(B14:C14),0) -> 0 | R14: =IF(C14,IF($B$7<0,,MIN($B$7-C14,$B$7)),) -> -7.29 | S14: =IF(B14,IF($B$7>0,,MAX($B$7-B14,$B$7)),) -> 0 | T14: =IF(C14,C14-$B$7+R14,) -> 0 | U14: =IF(B14,B14-$B$7+S14,) -> 0 | V14: =IF(T14,,IF(R14,TEXT(C14,"#")&IF(ISNUMBER(E14),TEXT(E14,", #%"),", "&E14),)) -> 8, | W14: =IF(U14,,IF(S14,TEXT(B14,"#")&TEXT(D14,", #%"),)) -> 0 | X14: =IF(T14,TEXT(C14,"#")&IF(ISNUMBER(E14),TEXT(E14,", #%"),", "&E14),) -> 0 | Y14: =IF(U14,TEXT(B14,"#")&TEXT(D14,", #%"),) -> 0
C15: 9 | F15: {=IF(AND(ISNUMBER(B15:C15)),IF(OR($B$7<C15,$D$7<E15),"Downside must be < Central",IF(OR($B$7>B15,$D$7>D15),"Upside must be > Central","OK")),"Enter numeric data")} -> Enter numeric data | O15: =A15 -> 0 | P15: =MAX(MIN(B15:C15),0) -> 9 | Q15: =MIN(MAX(B15:C15),0) -> 0 | R15: =IF(C15,IF($B$7<0,,MIN($B$7-C15,$B$7)),) -> -8.29 | S15: =IF(B15,IF($B$7>0,,MAX($B$7-B15,$B$7)),) -> 0 | T15: =IF(C15,C15-$B$7+R15,) -> 0 | U15: =IF(B15,B15-$B$7+S15,) -> 0 | V15: =IF(T15,,IF(R15,TEXT(C15,"#")&IF(ISNUMBER(E15),TEXT(E15,", #%"),", "&E15),)) -> 9, | W15: =IF(U15,,IF(S15,TEXT(B15,"#")&TEXT(D15,", #%"),)) -> 0 | X15: =IF(T15,TEXT(C15,"#")&IF(ISNUMBER(E15),TEXT(E15,", #%"),", "&E15),) -> 0 | Y15: =IF(U15,TEXT(B15,"#")&TEXT(D15,", #%"),) -> 0
A16: Other down, up (units) | F16: {=IF(AND(ISNUMBER(B16:C16)),IF(OR($B$7<C16,$D$7<E16),"Downside must be < Central",IF(OR($B$7>B16,$D$7>D16),"Upside must be > Central","OK")),"Enter numeric data")} -> Enter numeric data | O16: =A16 -> Other down, up (units) | P16: =MAX(MIN(B16:C16),0) -> 0 | Q16: =MIN(MAX(B16:C16),0) -> 0 | R16: =IF(C16,IF($B$7<0,,MIN($B$7-C16,$B$7)),) -> 0 | S16: =IF(B16,IF($B$7>0,,MAX($B$7-B16,$B$7)),) -> 0 | T16: =IF(C16,C16-$B$7+R16,) -> 0 | U16: =IF(B16,B16-$B$7+S16,) -> 0 | V16: =IF(T16,,IF(R16,TEXT(C16,"#")&IF(ISNUMBER(E16),TEXT(E16,", #%"),", "&E16),)) -> 0 | W16: =IF(U16,,IF(S16,TEXT(B16,"#")&TEXT(D16,", #%"),)) -> 0 | X16: =IF(T16,TEXT(C16,"#")&IF(ISNUMBER(E16),TEXT(E16,", #%"),", "&E16),) -> 0 | Y16: =IF(U16,TEXT(B16,"#")&TEXT(D16,", #%"),) -> 0
A17: Other down, up (units) | B17: =B7 -> 0.71 | C17: =B7-0.721 -> -0.011 | D17: =D7 -> 0.31 | E17: =D7-23.6% -> 0.074 | F17: {=IF(AND(ISNUMBER(B17:C17)),IF(OR($B$7<C17,$D$7<E17),"Downside must be < Central",IF(OR($B$7>B17,$D$7>D17),"Upside must be > Central","OK")),"Enter numeric data")} -> OK | O17: =A17 -> Other down, up (units) | P17: =MAX(MIN(B17:C17),0) -> 0 | Q17: =MIN(MAX(B17:C17),0) -> 0 | R17: =IF(C17,IF($B$7<0,,MIN($B$7-C17,$B$7)),) -> 0.71 | S17: =IF(B17,IF($B$7>0,,MAX($B$7-B17,$B$7)),) -> 0 | T17: =IF(C17,C17-$B$7+R17,) -> -0.011 | U17: =IF(B17,B17-$B$7+S17,) -> 0 | V17: =IF(T17,,IF(R17,TEXT(C17,"#")&IF(ISNUMBER(E17),TEXT(E17,", #%"),", "&E17),)) -> 0 | W17: =IF(U17,,IF(S17,TEXT(B17,"#")&TEXT(D17,", #%"),)) -> 0 | X17: =IF(T17,TEXT(C17,"#")&IF(ISNUMBER(E17),TEXT(E17,", #%"),", "&E17),) -> , 7% | Y17: =IF(U17,TEXT(B17,"#")&TEXT(D17,", #%"),) -> 0
A19: Chart

Sheet BB inflation
B2: Inflation
B3: Last updated 03/04/2024
B6: % change on previous year/1 | C6: 2022 | D6: 2023 | E6: 2024 | F6: 2025 | G6: 2026 | H6: 2027 | I6: 2028 | J6: 2029 | K6: 2030 | L6: 2031 | M6: 2032 | N6: 2033 | O6: 2034 | P6: 2035 | Q6: 2036 | R6: 2037 | S6: 2038 | T6: 2039 | U6: 2040 | V6: 2041 | W6: 2042 | X6: 2043 | Y6: 2044 | Z6: 2045 | AA6: 2046 | AB6: 2047 | AC6: 2048 | AD6: 2049 | AE6: 2050
B8: Algeria | C8: 9.27 | D8: 9.3 | E8: 6.02 | F8: 5 | G8: 4.25 | H8: 4.18 | I8: 3.97 | J8: 3.81 | K8: 3.74 | L8: 3.78 | M8: 3.81 | N8: 3.8 | O8: 3.78 | P8: 3.73 | Q8: 3.69 | R8: 3.66 | S8: 3.62 | T8: 3.57 | U8: 3.53 | V8: 3.52 | W8: 3.5 | X8: 3.49 | Y8: 3.5 | Z8: 3.5 | AA8: 3.54 | AB8: 3.57 | AC8: 3.58 | AD8: 3.56 | AE8: 3.54
B9: Angola | C9: 21.74 | D9: 14.4 | E9: 18.84 | F9: 10.655 | G9: 8.92 | H9: 8.2 | I9: 8.31 | J9: 8.025 | K9: 7.53 | L9: 6.79 | M9: 6.945 | N9: 6.955 | O9: 7.205 | P9: 7.38 | Q9: 7.415 | R9: 7.28 | S9: 7.11 | T9: 7.04 | U9: 6.995 | V9: 7.05 | W9: 7.165 | X9: 7.245 | Y9: 7.285 | Z9: 7.3 | AA9: 7.275 | AB9: 7.285 | AC9: 7.355 | AD9: 7.405 | AE9: 7.44
B10: Argentina | C10: 73.13 | D10: 134.04 | E10: 295.04 | F10: 60.81 | G10: 20.22 | H10: 10.35 | I10: 2.23 | J10: 0.56 | K10: 0.22 | L10: 0.38 | M10: 0.56 | N10: 0.75 | O10: 0.73 | P10: 0.55 | Q10: 0.4 | R10: 0.27 | S10: 0.24 | T10: 0.29 | U10: 0.45 | V10: 0.66 | W10: 0.93 | X10: 1.23 | Y10: 1.53 | Z10: 1.83 | AA10: 2.12 | AB10: 2.45 | AC10: 2.81 | AD10: 3.19 | AE10: 3.5
B11: Australia | C11: 6.61 | D11: 5.59 | E11: 3.26 | F11: 2.82 | G11: 2.53 | H11: 2.605 | I11: 2.515 | J11: 2.515 | K11: 2.505 | L11: 2.485 | M11: 2.45 | N11: 2.445 | O11: 2.445 | P11: 2.425 | Q11: 2.405 | R11: 2.395 | S11: 2.39 | T11: 2.39 | U11: 2.385 | V11: 2.37 | W11: 2.365 | X11: 2.355 | Y11: 2.35 | Z11: 2.355 | AA11: 2.36 | AB11: 2.36 | AC11: 2.355 | AD11: 2.35 | AE11: 2.345
B12: Azerbaijan | C12: 13.85 | D12: 10.44 | E12: 3.16 | F12: 6.5 | G12: 5.595 | H12: 5.65 | I12: 5.43 | J12: 5.32 | K12: 5.2 | L12: 5.085 | M12: 4.99 | N12: 4.895 | O12: 4.805 | P12: 4.73 | Q12: 4.655 | R12: 4.59 | S12: 4.52 | T12: 4.465 | U12: 4.405 | V12: 4.355 | W12: 4.305 | X12: 4.255 | Y12: 4.215 | Z12: 4.17 | AA12: 4.13 | AB12: 4.09 | AC12: 4.06 | AD12: 4.02 | AE12: 3.99
B13: Bangladesh | C13: 7.7 | D13: 9.855 | E13: 7.56 | F13: 6.005 | G13: 6.005 | H13: 5.525 | I13: 5.475 | J13: 5.525 | K13: 5.545 | L13: 5.55 | M13: 5.545 | N13: 5.54 | O13: 5.525 | P13: 5.505 | Q13: 5.48 | R13: 5.46 | S13: 5.445 | T13: 5.435 | U13: 5.425 | V13: 5.415 | W13: 5.405 | X13: 5.39 | Y13: 5.38 | Z13: 5.37 | AA13: 5.36 | AB13: 5.345 | AC13: 5.335 | AD13: 5.32 | AE13: 5.31
B14: Brazil | C14: 9.28 | D14: 4.59 | E14: 4.03 | F14: 3.415 | G14: 3.35 | H14: 3.19 | I14: 3.17 | J14: 3.175 | K14: 3.18 | L14: 3.18 | M14: 3.19 | N14: 3.205 | O14: 3.175 | P14: 3.175 | Q14: 3.155 | R14: 3.16 | S14: 3.155 | T14: 3.14 | U14: 3.14 | V14: 3.13 | W14: 3.115 | X14: 3.11 | Y14: 3.1 | Z14: 3.105 | AA14: 3.11 | AB14: 3.115 | AC14: 3.105 | AD14: 3.11 | AE14: 3.12
B15: Canada | C15: 6.8 | D15: 3.88 | E15: 2.545 | F15: 2.06 | G15: 2.08 | H15: 2.12 | I15: 2.08 | J15: 2.055 | K15: 2.04 | L15: 1.985 | M15: 1.995 | N15: 1.97 | O15: 1.995 | P15: 1.995 | Q15: 1.985 | R15: 1.97 | S15: 1.975 | T15: 1.975 | U15: 2 | V15: 1.995 | W15: 1.98 | X15: 1.99 | Y15: 2.005 | Z15: 1.995 | AA15: 1.975 | AB15: 1.99 | AC15: 1.99 | AD15: 1.99 | AE15: 2
B16: China | C16: 1.96 | D16: 0.24 | E16: 0.68 | F16: 1.685 | G16: 2.04 | H16: 2.245 | I16: 2.215 | J16: 2.16 | K16: 2.19 | L16: 2.21 | M16: 2.225 | N16: 2.235 | O16: 2.25 | P16: 2.255 | Q16: 2.255 | R16: 2.255 | S16: 2.265 | T16: 2.28 | U16: 2.28 | V16: 2.28 | W16: 2.28 | X16: 2.285 | Y16: 2.3 | Z16: 2.3 | AA16: 2.295 | AB16: 2.3 | AC16: 2.3 | AD16: 2.3 | AE16: 2.3
B17: Colombia | C17: 10.18 | D17: 11.74 | E17: 6.705 | F17: 4 | G17: 3.11 | H17: 3.17 | I17: 3.28 | J17: 3.155 | K17: 3.065 | L17: 3.015 | M17: 2.97 | N17: 2.935 | O17: 2.91 | P17: 2.88 | Q17: 2.855 | R17: 2.83 | S17: 2.81 | T17: 2.795 | U17: 2.775 | V17: 2.77 | W17: 2.765 | X17: 2.76 | Y17: 2.75 | Z17: 2.74 | AA17: 2.74 | AB17: 2.735 | AC17: 2.73 | AD17: 2.73 | AE17: 2.725
B18: Czech Republic | C18: 14.955 | D18: 11.3 | E18: 2.475 | F18: 1.98 | G18: 2.15 | H18: 2.175 | I18: 2.135 | J18: 2.095 | K18: 2.08 | L18: 2.055 | M18: 2.08 | N18: 2.13 | O18: 2.1 | P18: 2.07 | Q18: 2.005 | R18: 2.01 | S18: 2.01 | T18: 1.98 | U18: 2.005 | V18: 2.015 | W18: 1.995 | X18: 2.01 | Y18: 1.995 | Z18: 2.005 | AA18: 2.015 | AB18: 2.04 | AC18: 2.005 | AD18: 1.99 | AE18: 2.04
... B66: Ghana | C66: 31.92 | D66: 39.24 | E66: 18.725 | F66: 12.5 | G66: 8.715 | H66: 8.565 | I66: 8.245 | J66: 8.22 | K66: 8.2 | L66: 8.195 | M66: 8.18 | N66: 8.165 | O66: 8.155 | P66: 8.145 | Q66: 8.14 | R66: 8.13 | S66: 8.12 | T66: 8.115 | U66: 8.105 | V66: 8.095 | W66: 8.09 | X66: 8.085 | Y66: 8.075 | Z66: 8.07 | AA66: 8.065 | AB66: 8.055 | AC66: 8.045 | AD66: 8.035 | AE66: 8.03
B67: Iceland | D67: 8.63 | E67: 4.355 | F67: 2.21 | G67: 2.295 | H67: 2.52 | I67: 2.5 | J67: 2.5 | K67: 2.515 | L67: 2.515 | M67: 2.515 | N67: 2.515 | O67: 2.515 | P67: 2.515 | Q67: 2.515 | R67: 2.515 | S67: 2.515 | T67: 2.515 | U67: 2.515 | V67: 2.515 | W67: 2.515 | X67: 2.515 | Y67: 2.515 | Z67: 2.515 | AA67: 2.515 | AB67: 2.515 | AC67: 2.515 | AD67: 2.515 | AE67: 2.515
B69: Austria | C69: 8.585 | D69: 7.76 | E69: 3.04 | F69: 1.615 | G69: 2.055 | H69: 2.16 | I69: 2.14 | J69: 2.13 | K69: 2.115 | L69: 2.14 | M69: 2.135 | N69: 2.18 | O69: 2.16 | P69: 2.155 | Q69: 2.145 | R69: 2.16 | S69: 2.175 | T69: 2.155 | U69: 2.165 | V69: 2.155 | W69: 2.13 | X69: 2.13 | Y69: 2.115 | Z69: 2.125 | AA69: 2.115 | AB69: 2.125 | AC69: 2.11 | AD69: 2.115 | AE69: 2.125
B70: Belgium | C70: 9.965 | D70: 3.165 | E70: 3.075 | F70: 2 | G70: 1.745 | H70: 1.905 | I70: 2.015 | J70: 2.03 | K70: 2.06 | L70: 2.01 | M70: 1.985 | N70: 1.995 | O70: 1.95 | P70: 1.985 | Q70: 1.97 | R70: 1.955 | S70: 1.945 | T70: 1.925 | U70: 1.92 | V70: 1.98 | W70: 1.975 | X70: 1.99 | Y70: 1.975 | Z70: 1.98 | AA70: 1.995 | AB70: 2 | AC70: 1.98 | AD70: 1.99 | AE70: 1.995
B71: Cyprus | C71: 8.25 | D71: 3.93 | E71: 2.345 | F71: 1.87 | G71: 2.035 | H71: 2.14 | I71: 2.155 | J71: 2.275 | K71: 2.31 | L71: 2.325 | M71: 2.32 | N71: 2.37 | O71: 2.305 | P71: 2.255 | Q71: 2.195 | R71: 2.18 | S71: 2.145 | T71: 2.11 | U71: 2.115 | V71: 2.11 | W71: 2.08 | X71: 2.09 | Y71: 2.07 | Z71: 2.065 | AA71: 2.07 | AB71: 2.08 | AC71: 2.05 | AD71: 2.045 | AE71: 2.065
B72: Finland | C72: 7.145 | D72: 5.295 | E72: 1.87 | F72: 1.965 | G72: 1.985 | H72: 2.075 | I72: 2.08 | J72: 2.14 | K72: 2.125 | L72: 2.04 | M72: 2.06 | N72: 2.125 | O72: 2.16 | P72: 2.12 | Q72: 2.185 | R72: 2.145 | S72: 2.21 | T72: 2.15 | U72: 2.13 | V72: 2.145 | W72: 2.065 | X72: 2.115 | Y72: 2.09 | Z72: 2.165 | AA72: 2.085 | AB72: 2.1 | AC72: 2.06 | AD72: 2.06 | AE72: 2.065
B73: France | C73: 5.565 | D73: 5.27 | E73: 2.73 | F73: 1.5 | G73: 1.57 | H73: 1.945 | I73: 1.965 | J73: 1.985 | K73: 1.955 | L73: 2.01 | M73: 2.025 | N73: 2.05 | O73: 2.04 | P73: 2.045 | Q73: 2.05 | R73: 2.06 | S73: 2.06 | T73: 2.055 | U73: 2.06 | V73: 2.065 | W73: 2.035 | X73: 2.04 | Y73: 2.03 | Z73: 2.02 | AA73: 2.025 | AB73: 2.035 | AC73: 2.02 | AD73: 2.025 | AE73: 2.04
B74: Germany | C74: 7.78 | D74: 5.975 | E74: 1.92 | F74: 1.315 | G74: 1.505 | H74: 1.795 | I74: 1.98 | J74: 2.05 | K74: 2.025 | L74: 2.1 | M74: 2.205 | N74: 2.375 | O74: 2.355 | P74: 2.33 | Q74: 2.29 | R74: 2.295 | S74: 2.285 | T74: 2.235 | U74: 2.22 | V74: 2.215 | W74: 2.15 | X74: 2.11 | Y74: 2.075 | Z74: 2.045 | AA74: 2.01 | AB74: 2.03 | AC74: 1.995 | AD74: 1.97 | AE74: 1.99
B75: Greece | C75: 9.475 | D75: 3.805 | E75: 2.525 | F75: 1.645 | G75: 1.815 | H75: 1.92 | I75: 1.97 | J75: 1.9 | K75: 1.9 | L75: 1.895 | M75: 1.875 | N75: 1.915 | O75: 1.92 | P75: 1.935 | Q75: 1.92 | R75: 1.925 | S75: 1.925 | T75: 1.92 | U75: 1.935 | V75: 1.94 | W75: 1.925 | X75: 1.925 | Y75: 1.915 | Z75: 1.92 | AA75: 1.925 | AB75: 1.94 | AC75: 1.935 | AD75: 1.93 | AE75: 1.945
B76: Ireland | C76: 7.94 | D76: 5.745 | E76: 1.955 | F76: 1.77 | G76: 1.78 | H76: 1.855 | I76: 1.825 | J76: 1.89 | K76: 1.915 | L76: 1.955 | M76: 1.985 | N76: 1.985 | O76: 1.985 | P76: 1.97 | Q76: 1.965 | R76: 1.95 | S76: 1.92 | T76: 1.92 | U76: 1.92 | V76: 1.92 | W76: 1.92 | X76: 1.92 | Y76: 1.92 | Z76: 1.92 | AA76: 1.92 | AB76: 1.92 | AC76: 1.92 | AD76: 1.92 | AE76: 1.92
B77: Italy | C77: 8.47 | D77: 5.76 | E77: 1.535 | F77: 1.865 | G77: 1.73 | H77: 1.775 | I77: 1.805 | J77: 1.795 | K77: 1.8 | L77: 1.825 | M77: 1.865 | N77: 1.9 | O77: 1.92 | P77: 1.945 | Q77: 1.945 | R77: 1.95 | S77: 1.95 | T77: 1.95 | U77: 1.955 | V77: 1.955 | W77: 1.96 | X77: 1.97 | Y77: 1.985 | Z77: 1.97 | AA77: 1.955 | AB77: 1.94 | AC77: 1.945 | AD77: 1.95 | AE77: 1.95
B78: Malta | C78: 6.13 | D78: 5.56 | E78: 2.78 | F78: 1.965 | G78: 1.9 | H78: 1.855 | I78: 1.89 | J78: 1.9 | K78: 1.905 | L78: 1.935 | M78: 1.94 | N78: 1.945 | O78: 1.94 | P78: 1.93 | Q78: 1.925 | R78: 1.925 | S78: 1.925 | T78: 1.92 | U78: 1.92 | V78: 1.925 | W78: 1.925 | X78: 1.925 | Y78: 1.925 | Z78: 1.925 | AA78: 1.93 | AB78: 1.935 | AC78: 1.935 | AD78: 1.935 | AE78: 1.94
B79: Netherlands | C79: 10.82 | D79: 3.97 | E79: 2.125 | F79: 1.825 | G79: 1.725 | H79: 1.86 | I79: 1.995 | J79: 2 | K79: 2.015 | L79: 2 | M79: 2.015 | N79: 2.055 | O79: 2.055 | P79: 2.06 | Q79: 2.065 | R79: 2.065 | S79: 2.06 | T79: 2.06 | U79: 2.06 | V79: 2.045 | W79: 2.02 | X79: 2.04 | Y79: 2 | Z79: 2.015 | AA79: 2.025 | AB79: 2.01 | AC79: 1.985 | AD79: 1.975 | AE79: 1.985
B80: Portugal | C80: 7.96 | D80: 4.79 | E80: 2.285 | F80: 1.93 | G80: 1.725 | H80: 1.795 | I80: 1.74 | J80: 1.765 | K80: 1.825 | L80: 1.85 | M80: 1.86 | N80: 1.89 | O80: 1.905 | P80: 1.915 | Q80: 1.905 | R80: 1.91 | S80: 1.925 | T80: 1.92 | U80: 1.915 | V80: 1.925 | W80: 1.935 | X80: 1.95 | Y80: 1.955 | Z80: 1.97 | AA80: 1.96 | AB80: 1.97 | AC80: 1.975 | AD80: 1.98 | AE80: 1.995
... B84: Luxembourg | C84: 7.25 | D84: 3.33 | E84: 2.195 | F84: 1.9 | G84: 2.005 | H84: 2.22 | I84: 2.245 | J84: 2.175 | K84: 2.07 | L84: 2.115 | M84: 2.135 | N84: 2.19 | O84: 2.15 | P84: 2.14 | Q84: 2.105 | R84: 2.065 | S84: 2.03 | T84: 2.01 | U84: 2.025 | V84: 2.01 | W84: 1.975 | X84: 1.975 | Y84: 1.975 | Z84: 1.97 | AA84: 1.98 | AB84: 1.995 | AC84: 1.985 | AD84: 1.985 | AE84: 1.995
B86: /1 Inflation is measured as the percentage change between the average level of the consumer price index in one year compared to the previous year.

Sheet BB FX
B2: Exchange Rates
B3: Last updated 29/03/2023
B6: Currency against the US$ | C6: 2022 | D6: 2023 | E6: 2024 | F6: 2025 | G6: 2026 | H6: 2027 | I6: 2028 | J6: 2029 | K6: 2030 | L6: 2031 | M6: 2032 | N6: 2033 | O6: 2034 | P6: 2035 | Q6: 2036 | R6: 2037 | S6: 2038 | T6: 2039 | U6: 2040 | V6: 2041 | W6: 2042 | X6: 2043 | Y6: 2044 | Z6: 2045 | AA6: 2046 | AB6: 2047 | AC6: 2048 | AD6: 2049 | AE6: 2050
B8: Algeria | C8: 142.01 | D8: 135.84 | E8: 137 | F8: 141.54 | G8: 146.17 | H8: 149.7 | I8: 151.42 | J8: 153.23 | K8: 154.36 | L8: 155.72 | M8: 157.08 | N8: 158.65 | O8: 160.26 | P8: 161.94 | Q8: 163.44 | R8: 164.84 | S8: 166.21 | T8: 167.53 | U8: 168.78 | V8: 169.94 | W8: 170.96 | X8: 171.76 | Y8: 172.36 | Z8: 172.83 | AA8: 173.25 | AB8: 173.65 | AC8: 174.08 | AD8: 174.55 | AE8: 175.1
B9: Angola | C9: 460.52 | D9: 684.96 | E9: 839.23 | F9: 859.49 | G9: 889.53 | H9: 924.17 | I9: 961.24 | J9: 1001.33 | K9: 1043.2 | L9: 1086.2 | M9: 1130.81 | N9: 1177.22 | O9: 1225.4 | P9: 1275.79 | Q9: 1326.3 | R9: 1376.4 | S9: 1427.12 | T9: 1478.75 | U9: 1531.72 | V9: 1586.32 | W9: 1642.8 | X9: 1701.35 | Y9: 1762.2 | Z9: 1825.54 | AA9: 1891.55 | AB9: 1960.38 | AC9: 2032.24 | AD9: 2107.28 | AE9: 2185.66
B10: Argentina | C10: 130.71 | D10: 296.52 | E10: 1300.83 | F10: 2102.32 | G10: 2469.75 | H10: 2634.49 | I10: 2619.77 | J10: 2529.02 | K10: 2433.57 | L10: 2355.59 | M10: 2301.7 | N10: 2263.18 | O10: 2230.27 | P10: 2202.11 | Q10: 2174.85 | R10: 2146.67 | S10: 2119.45 | T10: 2094.98 | U10: 2074.84 | V10: 2059.63 | W10: 2049.74 | X10: 2045.14 | Y10: 2045.66 | Z10: 2051.4 | AA10: 2062.72 | AB10: 2080.18 | AC10: 2103.98 | AD10: 2134.13 | AE10: 2169.77
